Workbook
Name Conf.Interval: 'Sec7-2out'!$C$39
Name min_range: 'Sec7-2out'!$C$40
Name software: 'Sec7-2out'!$E$3
Name t_c: 'Sec7-2out'!$B$43

Sheet Sec7-2out
A1: Std140_TF_Class2_Results.xls, sheet "TF_Class2_Output"
D3: Software name: | E3: Pinocchio-EP / EnergyPlus 26.1 | H3: Enter the name and version number of the software being tested in Cell E3 (merged cells);
I4: use abbreviation if needed, so that name of tested software fits well on the charts
D6: Organizations submitting results: | E6: ERGO Energy LLP | H6: Enter the name of the organization submitting results in Cell E5 (merged cells)
A8: Results: | C8: Instructions: Enter test case results as specified in Sections 12.3.1 and 12.3.2 next to test case name in yellow cells, for heating and cooling seasons for the entire year or some other reasonable
D9: length as defined by the tool being tested in units of million Btu; see row 31 for season entry instructions. (Note, currently shown load values are automatically calculated
D10: average values of example results (average of subsets of results for L302A - L324A); simply overwrite those formulas when entering values for the tested program.)
A11: Tier 1 Test Cases: | H11: Tier 2 Test Cases
B12: Heating Cases: | E12: Cooling Cases: | I12: Heating Cases: | L12: Cooling Cases:
C13: Heating Load | F13: Cooling Load | J13: Heating Load | M13: Cooling Load
C14: (Million Btu) | F14: (Million Btu) | J14: (Million Btu) | M14: (Million Btu)
B15: L100AC | C15: 52.09 | E15: L100AL | F15: 47.79 | I15: L165AC | J15: 56.87 | L15: L165AL | M15: 48.69
B16: L110AC | C16: 77.77 | E16: L110AL | F16: 51.09 | I16: P100AC | L16: P100AC
B17: L120AC | C17: 39.67 | E17: L120AL | F17: 43.76 | I17: P105AC | L17: P105AC
B18: L130AC | C18: 42.29 | E18: L130AL | F18: 35.24 | I18: P110AC | L18: P110AC
B19: L140AC | C19: 49.39 | E19: L140AL | F19: 22.66 | I19: P140AC | L19: P140AC
B20: L150AC | C20: 44.05 | E20: L150AL | F20: 59.9 | I20: P150AC | L20: P150AC
B21: L155AC | C21: 46.85 | E21: L155AL | F21: 45.09
B22: L160AC | C22: 52.81 | E22: L160AL | F22: 57.13
B23: L170AC | C23: 62.96 | E23: L170AL | F23: 38.72
B24: L200AC | C24: 131.29 | E24: L200AL | F24: 59.88
B25: L202AC | C25: 136.97 | E25: L202AL | F25: 50.17
B26: L302AB | C26: 60.75
B27: L304AB | C27: 50.02
B28: L322AB | C28: 70.67
B29: L324AB | C29: 52.3
A31: Seasons: | C31: Instructions: Enter first and last Julian date (365 day year) for each season in yellow cells. | K31: Example Seasons:
B32: Heating: | C32: First day | D32: Last day | K32: Heating: | L32: 39696 | M32: 39548
C33: 1 | D33: 365 | L33: 248 | M33: 100
B34: Cooling: | C34: First day | D34: Last day | K34: Cooling: | L34: 39578 | M34: 39706
C35: 1 | D35: 365 | L35: 131 | M35: 258
A37: Statistics: | C37: Instructions: select confidence interval from pull down list and enter
D38: minimum range for criteria range bands
B39: Conf.Interval: | C39: 0.9
B40: min range: | C40: 4 | D40: 10^6 Btu
B42: t_c | C42: n | D42: 0.8 | E42: 0.9 | F42: 0.95
B43: =IF(C39=D42,D43,IF(C39=E42,E43,IF(C39=F42,F43,0))) | C43: 3 | D43: 1.886 | E43: 2.92 | F43: 4.303

Sheet Tables_B20
A1: Example Results Seasonal Loads
B2: Table B20-1. HERS BESTEST Tier-1 Example Results – Annual or Seasonal Heating Loads (10^6 Btu/y) for Colorado Springs, CO
B3: Example Results: | F3: Statistics:
B4: Test Case | C4: BLAST 3.0 | D4: DOE 2.1E | E4: SERIRES 5.7 | F4: min | G4: max | H4: mean | I4: (max -min) /mean**
B5: L100AC | C5: ='BLAST-HtgRes'!C$30 | D5: ='DOE-HtgRes'!C$30 | E5: ='SRES-HtgRes'!C$30 | F5: =MIN(C5:E5) | G5: =MAX(C5:E5) | H5: =AVERAGE(C5:E5) | I5: =ABS((G5-F5)/AVERAGE(C5:E5))
B6: L110AC | C6: ='BLAST-HtgRes'!D$30 | D6: ='DOE-HtgRes'!D$30 | E6: ='SRES-HtgRes'!D$30 | F6: =MIN(C6:E6) | G6: =MAX(C6:E6) | H6: =AVERAGE(C6:E6) | I6: =ABS((G6-F6)/AVERAGE(C6:E6))
B7: L120AC | C7: ='BLAST-HtgRes'!E$30 | D7: ='DOE-HtgRes'!E$30 | E7: ='SRES-HtgRes'!E$30 | F7: =MIN(C7:E7) | G7: =MAX(C7:E7) | H7: =AVERAGE(C7:E7) | I7: =ABS((G7-F7)/AVERAGE(C7:E7))
B8: L130AC | C8: ='BLAST-HtgRes'!F$30 | D8: ='DOE-HtgRes'!F$30 | E8: ='SRES-HtgRes'!F$30 | F8: =MIN(C8:E8) | G8: =MAX(C8:E8) | H8: =AVERAGE(C8:E8) | I8: =ABS((G8-F8)/AVERAGE(C8:E8))
B9: L140AC | C9: ='BLAST-HtgRes'!G$30 | D9: ='DOE-HtgRes'!G$30 | E9: ='SRES-HtgRes'!G$30 | F9: =MIN(C9:E9) | G9: =MAX(C9:E9) | H9: =AVERAGE(C9:E9) | I9: =ABS((G9-F9)/AVERAGE(C9:E9))
B10: L150AC | C10: ='BLAST-HtgRes'!H$30 | D10: ='DOE-HtgRes'!H$30 | E10: ='SRES-HtgRes'!H$30 | F10: =MIN(C10:E10) | G10: =MAX(C10:E10) | H10: =AVERAGE(C10:E10) | I10: =ABS((G10-F10)/AVERAGE(C10:E10))
B11: L155AC | C11: ='BLAST-HtgRes'!I$30 | D11: ='DOE-HtgRes'!I$30 | E11: ='SRES-HtgRes'!I$30 | F11: =MIN(C11:E11) | G11: =MAX(C11:E11) | H11: =AVERAGE(C11:E11) | I11: =ABS((G11-F11)/AVERAGE(C11:E11))
B12: L160AC | C12: ='BLAST-HtgRes'!J$30 | D12: ='DOE-HtgRes'!J$30 | E12: ='SRES-HtgRes'!J$30 | F12: =MIN(C12:E12) | G12: =MAX(C12:E12) | H12: =AVERAGE(C12:E12) | I12: =ABS((G12-F12)/AVERAGE(C12:E12))
B13: L170AC | C13: ='BLAST-HtgRes'!K$30 | D13: ='DOE-HtgRes'!K$30 | E13: ='SRES-HtgRes'!K$30 | F13: =MIN(C13:E13) | G13: =MAX(C13:E13) | H13: =AVERAGE(C13:E13) | I13: =ABS((G13-F13)/AVERAGE(C13:E13))
B14: L200AC | C14: ='BLAST-HtgRes'!L$30 | D14: ='DOE-HtgRes'!L$30 | E14: ='SRES-HtgRes'!L$30 | F14: =MIN(C14:E14) | G14: =MAX(C14:E14) | H14: =AVERAGE(C14:E14) | I14: =ABS((G14-F14)/AVERAGE(C14:E14))
B15: L202AC | C15: ='BLAST-HtgRes'!M$30 | D15: ='DOE-HtgRes'!M$30 | E15: ='SRES-HtgRes'!M$30 | F15: =MIN(C15:E15) | G15: =MAX(C15:E15) | H15: =AVERAGE(C15:E15) | I15: =ABS((G15-F15)/AVERAGE(C15:E15))
B16: L302AC | C16: ='BLAST-HtgRes'!N$30 | D16: ='DOE-HtgRes'!N$30 | E16: ='SRES-HtgRes'!N$30 | F16: =MIN(C16:E16) | G16: =MAX(C16:E16) | H16: =AVERAGE(C16:E16) | I16: =ABS((G16-F16)/AVERAGE(C16:E16))
B17: L302BC | C17: ='BLAST-HtgRes'!O$30 | D17: ='DOE-HtgRes'!O$30 | E17: ='SRES-HtgRes'!O$30 | F17: =MIN(C17:E17) | G17: =MAX(C17:E17) | H17: =AVERAGE(C17:E17) | I17: =ABS((G17-F17)/AVERAGE(C17:E17))
B18: L304AC | C18: ='BLAST-HtgRes'!P$30 | D18: ='DOE-HtgRes'!P$30 | E18: ='SRES-HtgRes'!P$30 | F18: =MIN(C18:E18) | G18: =MAX(C18:E18) | H18: =AVERAGE(C18:E18) | I18: =ABS((G18-F18)/AVERAGE(C18:E18))
B19: L304BC | C19: ='BLAST-HtgRes'!Q$30 | D19: ='DOE-HtgRes'!Q$30 | E19: ='SRES-HtgRes'!Q$30 | F19: =MIN(C19:E19) | G19: =MAX(C19:E19) | H19: =AVERAGE(C19:E19) | I19: =ABS((G19-F19)/AVERAGE(C19:E19))
B20: L322A1 | C20: ='BLAST-HtgRes'!R$30 | D20: ='DOE-HtgRes'!R$30 | E20: ='SRES-HtgRes'!R$30 | F20: =MIN(C20:E20) | G20: =MAX(C20:E20) | H20: =AVERAGE(C20:E20) | I20: =ABS((G20-F20)/AVERAGE(C20:E20))
B21: L322A2 | C21: ='BLAST-HtgRes'!S$30 | D21: ='DOE-HtgRes'!S$30 | E21: ='SRES-HtgRes'!S$30 | F21: =MIN(C21:E21) | G21: =MAX(C21:E21) | H21: =AVERAGE(C21:E21) | I21: =ABS((G21-F21)/AVERAGE(C21:E21))
B22: L322B1 | C22: ='BLAST-HtgRes'!T$30 | D22: ='DOE-HtgRes'!T$30 | E22: ='SRES-HtgRes'!T$30 | F22: =MIN(C22:E22) | G22: =MAX(C22:E22) | H22: =AVERAGE(C22:E22) | I22: =ABS((G22-F22)/AVERAGE(C22:E22))
B23: L322B2 | C23: ='BLAST-HtgRes'!U$30 | D23: ='DOE-HtgRes'!U$30 | E23: ='SRES-HtgRes'!U$30 | F23: =MIN(C23:E23) | G23: =MAX(C23:E23) | H23: =AVERAGE(C23:E23) | I23: =ABS((G23-F23)/AVERAGE(C23:E23))
B24: L324A1 | C24: ='BLAST-HtgRes'!V$30 | D24: ='DOE-HtgRes'!V$30 | E24: ='SRES-HtgRes'!V$30 | F24: =MIN(C24:E24) | G24: =MAX(C24:E24) | H24: =AVERAGE(C24:E24) | I24: =ABS((G24-F24)/AVERAGE(C24:E24))
B25: L324A2 | C25: ='BLAST-HtgRes'!W$30 | D25: ='DOE-HtgRes'!W$30 | E25: ='SRES-HtgRes'!W$30 | F25: =MIN(C25:E25) | G25: =MAX(C25:E25) | H25: =AVERAGE(C25:E25) | I25: =ABS((G25-F25)/AVERAGE(C25:E25))
B26: L324B1 | C26: ='BLAST-HtgRes'!X$30 | D26: ='DOE-HtgRes'!X$30 | E26: ='SRES-HtgRes'!X$30 | F26: =MIN(C26:E26) | G26: =MAX(C26:E26) | H26: =AVERAGE(C26:E26) | I26: =ABS((G26-F26)/AVERAGE(C26:E26))
B27: L324B2 | C27: ='BLAST-HtgRes'!Y$30 | D27: ='DOE-HtgRes'!Y$30 | E27: ='SRES-HtgRes'!Y$30 | F27: =MIN(C27:E27) | G27: =MAX(C27:E27) | H27: =AVERAGE(C27:E27) | I27: =ABS((G27-F27)/AVERAGE(C27:E27))
B28: ** ABS [(max - min) / (mean of Example Results)]
B30: Table B20-2. HERS BESTEST Tier-1 Example Results – Delta Annual or Seasonal Heating Loads (10^6 Btu/y) for Colorado Springs, CO
B31: Example Results: | F31: Statistics:
B32: Test Case Delta | C32: BLAST 3.0 | D32: DOE 2.1E | E32: SERIRES 5.7 | F32: min | G32: max | H32: mean | I32: (max -min) /mean**
B33: L110AC-L100AC | C33: =C6-C5 | D33: =D6-D5 | E33: =E6-E5 | F33: =MIN(C33:E33) | G33: =MAX(C33:E33) | H33: =AVERAGE(C33:E33) | I33: =ABS((G33-F33)/AVERAGE(C33:E33))
B34: L120AC-L100AC | C34: =C7-C5 | D34: =D7-D5 | E34: =E7-E5 | F34: =MIN(C34:E34) | G34: =MAX(C34:E34) | H34: =AVERAGE(C34:E34) | I34: =ABS((G34-F34)/AVERAGE(C34:E34))
B35: L130AC-L100AC | C35: =C8-C5 | D35: =D8-D5 | E35: =E8-E5 | F35: =MIN(C35:E35) | G35: =MAX(C35:E35) | H35: =AVERAGE(C35:E35) | I35: =ABS((G35-F35)/AVERAGE(C35:E35))
B36: L140AC-L100AC | C36: =C9-C5 | D36: =D9-D5 | E36: =E9-E5 | F36: =MIN(C36:E36) | G36: =MAX(C36:E36) | H36: =AVERAGE(C36:E36) | I36: =ABS((G36-F36)/AVERAGE(C36:E36))
B37: L150AC-L100AC | C37: =C10-C5 | D37: =D10-D5 | E37: =E10-E5 | F37: =MIN(C37:E37) | G37: =MAX(C37:E37) | H37: =AVERAGE(C37:E37) | I37: =ABS((G37-F37)/AVERAGE(C37:E37))
B38: L155AC-L150AC | C38: =C11-C10 | D38: =D11-D10 | E38: =E11-E10 | F38: =MIN(C38:E38) | G38: =MAX(C38:E38) | H38: =AVERAGE(C38:E38) | I38: =ABS((G38-F38)/AVERAGE(C38:E38))
B39: L160AC-L100AC | C39: =C12-C5 | D39: =D12-D5 | E39: =E12-E5 | F39: =MIN(C39:E39) | G39: =MAX(C39:E39) | H39: =AVERAGE(C39:E39) | I39: =ABS((G39-F39)/AVERAGE(C39:E39))
B40: L170AC-L100AC | C40: =C13-C5 | D40: =D13-D5 | E40: =E13-E5 | F40: =MIN(C40:E40) | G40: =MAX(C40:E40) | H40: =AVERAGE(C40:E40) | I40: =ABS((G40-F40)/AVERAGE(C40:E40))
B41: L200AC-L100AC | C41: =C14-C5 | D41: =D14-D5 | E41: =E14-E5 | F41: =MIN(C41:E41) | G41: =MAX(C41:E41) | H41: =AVERAGE(C41:E41) | I41: =ABS((G41-F41)/AVERAGE(C41:E41))
...

Sheet BLAST-HtgRes
B1: Table B20-9. BLAST 3.0 Monthly and Total Heating Loads (million Btu) | AA1: Table B20-10. BLAST 3.0 Monthly and Total Heating Loads (million Btu)
C2: L100AC | D2: L110AC | E2: L120AC | F2: L130AC | G2: L140AC | H2: L150AC | I2: L155AC | J2: L160AC | K2: L170AC | L2: L200AC | M2: L202AC | N2: L302AC | O2: L302BC | P2: L304AC | Q2: L304BC | R2: L322A1 | S2: L322A2 | T2: L322B1 | U2: L322B2 | V2: L324A1 | W2: L324A2 | X2: L324B1 | Y2: L324B2 | AB2: L165AC | AC2: P100AC | AD2: P105AC | AE2: P110AC | AF2: P140AC | AG2: P150AC
A3: 1 | B3: Jan | C3: 11.3 | D3: 15.27 | E3: 9.34 | F3: 8.72 | G3: 8.96 | H3: 9.61 | I3: 9.69 | J3: 11.94 | K3: 12.68 | L3: 22.73 | M3: 23.21 | N3: 12.52 | O3: 12.22 | P3: 10.86 | Q3: 10.5 | R3: 16.19 | S3: 16.41 | T3: 15.72 | U3: 16.37 | V3: 11.91 | W3: 11.99 | X3: 11.16 | Y3: 11.26 | AA3: Jan | AB3: 12.63 | AC3: 2.44 | AD3: 2.45 | AE3: 4.2 | AF3: 5.68 | AG3: 5.44
A4: 2 | B4: Feb | C4: 9.74 | D4: 13.21 | E4: 8.07 | F4: 7.5 | G4: 7.79 | H4: 8.54 | I4: 8.8 | J4: 9.99 | K4: 11 | L4: 19.74 | M4: 20.19 | N4: 10.81 | O4: 10.87 | P4: 9.37 | Q4: 9.34 | R4: 14.05 | S4: 14.26 | T4: 14.02 | U4: 14.54 | V4: 10.29 | W4: 10.36 | X4: 9.84 | Y4: 10.14 | AA4: Feb | AB4: 10.63 | AC4: 2.41 | AD4: 2.61 | AE4: 3.88 | AF4: 4.98 | AG4: 4.68
A5: 3 | B5: Mar | C5: 9.04 | D5: 12.41 | E5: 7.43 | F5: 6.9 | G5: 7.39 | H5: 8.23 | I5: 8.87 | J5: 8.76 | K5: 10.39 | L5: 18.86 | M5: 19.37 | N5: 10.11 | O5: 9.96 | P5: 8.7 | Q5: 8.51 | R5: 13.25 | S5: 13.46 | T5: 12.9 | U5: 13.56 | V5: 9.53 | W5: 9.61 | X5: 8.87 | Y5: 9.3 | AA5: Mar | AB5: 9.33 | AC5: 2.23 | AD5: 3.04 | AE5: 3.63 | AF5: 4.67 | AG5: 3.87
A6: 4 | B6: Apr | C6: 5.17 | D6: 7.28 | E6: 4.16 | F6: 3.81 | G6: 4.24 | H6: 5.13 | I6: 5.75 | J6: 4.7 | K6: 6.26 | L6: 11.52 | M6: 11.93 | N6: 5.92 | O6: 5.35 | P6: 5.01 | Q6: 4.58 | R6: 7.82 | S6: 7.96 | T6: 6.62 | U6: 7.39 | V6: 5.42 | W6: 5.45 | X6: 4.43 | Y6: 4.96 | AA6: Apr | AB6: 4.95 | AC6: 1.29 | AD6: 2.18 | AE6: 2.15 | AF6: 2.48 | AG6: 1.67
A7: 5 | B7: May | C7: 2.43 | D7: 3.66 | E7: 1.84 | F7: 1.63 | G7: 1.89 | H7: 2.54 | I7: 2.79 | J7: 2.17 | K7: 3.3 | L7: 6.33 | M7: 6.57 | N7: 2.99 | O7: 2.13 | P7: 2.42 | Q7: 1.75 | R7: 3.95 | S7: 3.96 | T7: 2.18 | U7: 2.9 | V7: 2.49 | W7: 2.46 | X7: 1.36 | Y7: 1.88 | AA7: May | AB7: 2.29 | AC7: 0.36 | AD7: 0.62 | AE7: 0.81 | AF7: 0.8 | AG7: 0.36
A8: 6 | B8: Jun | C8: 0.69 | D8: 1.2 | E8: 0.46 | F8: 0.4 | G8: 0.47 | H8: 0.76 | I8: 0.82 | J8: 0.6 | K8: 1.11 | L8: 2.55 | M8: 2.65 | N8: 1.01 | O8: 0.44 | P8: 0.73 | Q8: 0.34 | R8: 1.29 | S8: 1.2 | T8: 0.38 | U8: 0.58 | V8: 0.66 | W8: 0.62 | X8: 0.22 | Y8: 0.38 | AA8: Jun | AB8: 0.63 | AC8: 0.05 | AD8: 0.09 | AE8: 0.18 | AF8: 0.15 | AG8: 0.03
A9: 7 | B9: Jul | C9: 0.06 | D9: 0.2 | E9: 0.02 | F9: 0.01 | G9: 0.02 | H9: 0.07 | I9: 0.08 | J9: 0.05 | K9: 0.23 | L9: 0.79 | M9: 0.83 | N9: 0.19 | O9: 0 | P9: 0.09 | Q9: 0 | R9: 0.21 | S9: 0.15 | T9: 0 | U9: 0 | V9: 0.03 | W9: 0.02 | X9: 0 | Y9: 0 | AA9: Jul | AB9: 0.05 | AC9: 0 | AD9: 0 | AE9: 0 | AF9: 0 | AG9: 0
A10: 8 | B10: Aug | C10: 0.13 | D10: 0.34 | E10: 0.05 | F10: 0.04 | G10: 0.04 | H10: 0.13 | I10: 0.17 | J10: 0.11 | K10: 0.37 | L10: 1.16 | M10: 1.22 | N10: 0.31 | O10: 0 | P10: 0.17 | Q10: 0 | R10: 0.35 | S10: 0.27 | T10: 0 | U10: 0 | V10: 0.09 | W10: 0.06 | X10: 0 | Y10: 0 | AA10: Aug | AB10: 0.12 | AC10: 0 | AD10: 0 | AE10: 0 | AF10: 0 | AG10: 0
A11: 9 | B11: Sep | C11: 1.2 | D11: 1.92 | E11: 0.82 | F11: 0.7 | G11: 0.79 | H11: 1.1 | I11: 1.25 | J11: 1.13 | K11: 1.8 | L11: 3.68 | M11: 3.8 | N11: 1.62 | O11: 0.68 | P11: 1.25 | Q11: 0.48 | R11: 2.05 | S11: 1.96 | T11: 0.28 | U11: 0.79 | V11: 1.18 | W11: 1.09 | X11: 0.15 | Y11: 0.56 | AA11: Sep | AB11: 1.2 | AC11: 0 | AD11: 0 | AE11: 0.13 | AF11: 0.11 | AG11: 0
A12: 10 | B12: Oct | C12: 3.46 | D12: 5.03 | E12: 2.66 | F12: 2.38 | G12: 2.71 | H12: 2.95 | I12: 3.12 | J12: 3.5 | K12: 4.46 | L12: 8.36 | M12: 8.6 | N12: 4.18 | O12: 3.09 | P12: 3.45 | Q12: 2.52 | R12: 5.39 | S12: 5.36 | T12: 3.22 | U12: 4.18 | V12: 3.56 | W12: 3.47 | X12: 2.03 | Y12: 2.72 | AA12: Oct | AB12: 3.78 | AC12: 0.23 | AD12: 0.27 | AE12: 0.75 | AF12: 1.28 | AG12: 0.5
A13: 11 | B13: Nov | C13: 8.18 | D13: 11.21 | E13: 6.7 | F13: 6.23 | G13: 6.66 | H13: 6.86 | I13: 6.99 | J13: 8.71 | K13: 9.5 | L13: 17.12 | M13: 17.54 | N13: 9.16 | O13: 8.94 | P13: 7.87 | Q13: 7.61 | R13: 11.96 | S13: 12.16 | T13: 11.61 | U13: 12.22 | V13: 8.63 | W13: 8.68 | X13: 7.98 | Y13: 8.35 | AA13: Nov | AB13: 9.37 | AC13: 1.11 | AD13: 1.15 | AE13: 2.68 | AF13: 4.13 | AG13: 3.45
A14: 12 | B14: Dec | C14: 10.54 | D14: 14.22 | E14: 8.72 | F14: 8.03 | G14: 8.19 | H14: 9.01 | I14: 9.06 | J14: 11.24 | K14: 11.96 | L14: 21.13 | M14: 21.56 | N14: 11.68 | O14: 11.56 | P14: 10.13 | Q14: 9.96 | R14: 15.14 | S14: 15.34 | T14: 14.89 | U14: 15.44 | V14: 11.12 | W14: 11.2 | X14: 10.55 | Y14: 10.85 | AA14: Dec | AB14: 11.86 | AC14: 2.19 | AD14: 2.19 | AE14: 3.96 | AF14: 5.14 | AG14: 5.1
B15: Tot | C15: 61.94 | D15: 85.93 | E15: 50.27 | F15: 46.34 | G15: 49.14 | H15: 54.92 | I15: 57.38 | J15: 62.88 | K15: 73.06 | L15: 133.97 | M15: 137.46 | N15: 70.48 | O15: 65.25 | P15: 60.06 | Q15: 55.59 | R15: 91.66 | S15: 92.5 | T15: 81.82 | U15: 87.97 | V15: 64.9 | W15: 65.02 | X15: 56.57 | Y15: 60.4 | AA15: Tot | AB15: 66.84 | AC15: 12.31 | AD15: 14.59 | AE15: 22.38 | AF15: 29.4 | AG15: 25.1
A16: Seasonal Values: | AA16: Tier 2 Results
B17: Htg_Coeff | C17: =C2 | D17: =D2 | E17: =E2 | F17: =F2 | G17: =G2 | H17: =H2 | I17: =I2 | J17: =J2 | ... Y17: =Y2 | AB17: =AB2 | AC17: =AC2 | AD17: =AD2 | AE17: =AE2 | AF17: =AF2 | AG17: =AG2
A18: 1 | B18: =Season_Coeff!N4 | C18: =IF($B18*C3>0,$B18*C3,"") | D18: =IF($B18*D3>0,$B18*D3,"") | E18: =IF($B18*E3>0,$B18*E3,"") | F18: =IF($B18*F3>0,$B18*F3,"") | G18: =IF($B18*G3>0,$B18*G3,"") | H18: =IF($B18*H3>0,$B18*H3,"") | I18: =IF($B18*I3>0,$B18*I3,"") | J18: =IF($B18*J3>0,$B18*J3,"") | ... Y18: =IF($B18*Y3>0,$B18*Y3,"") | AB18: =IF($B18*AB3>0,$B18*AB3,"") | AC18: =IF($B18*AC3>0,$B18*AC3,"") | AD18: =IF($B18*AD3>0,$B18*AD3,"") | AE18: =IF($B18*AE3>0,$B18*AE3,"") | AF18: =IF($B18*AF3>0,$B18*AF3,"") | AG18: =IF($B18*AG3>0,$B18*AG3,"")
A19: 2 | B19: =Season_Coeff!N5 | C19: =IF($B19*C4>0,$B19*C4,"") | D19: =IF($B19*D4>0,$B19*D4,"") | E19: =IF($B19*E4>0,$B19*E4,"") | F19: =IF($B19*F4>0,$B19*F4,"") | G19: =IF($B19*G4>0,$B19*G4,"") | H19: =IF($B19*H4>0,$B19*H4,"") | I19: =IF($B19*I4>0,$B19*I4,"") | J19: =IF($B19*J4>0,$B19*J4,"") | ... Y19: =IF($B19*Y4>0,$B19*Y4,"") | AB19: =IF($B19*AB4>0,$B19*AB4,"") | AC19: =IF($B19*AC4>0,$B19*AC4,"") | AD19: =IF($B19*AD4>0,$B19*AD4,"") | AE19: =IF($B19*AE4>0,$B19*AE4,"") | AF19: =IF($B19*AF4>0,$B19*AF4,"") | AG19: =IF($B19*AG4>0,$B19*AG4,"")
A20: 3 | B20: =Season_Coeff!N6 | C20: =IF($B20*C5>0,$B20*C5,"") | D20: =IF($B20*D5>0,$B20*D5,"") | E20: =IF($B20*E5>0,$B20*E5,"") | F20: =IF($B20*F5>0,$B20*F5,"") | G20: =IF($B20*G5>0,$B20*G5,"") | H20: =IF($B20*H5>0,$B20*H5,"") | I20: =IF($B20*I5>0,$B20*I5,"") | J20: =IF($B20*J5>0,$B20*J5,"") | ... Y20: =IF($B20*Y5>0,$B20*Y5,"") | AB20: =IF($B20*AB5>0,$B20*AB5,"") | AC20: =IF($B20*AC5>0,$B20*AC5,"") | AD20: =IF($B20*AD5>0,$B20*AD5,"") | AE20: =IF($B20*AE5>0,$B20*AE5,"") | AF20: =IF($B20*AF5>0,$B20*AF5,"") | AG20: =IF($B20*AG5>0,$B20*AG5,"")
A21: 4 | B21: =Season_Coeff!N7 | C21: =IF($B21*C6>0,$B21*C6,"") | D21: =IF($B21*D6>0,$B21*D6,"") | E21: =IF($B21*E6>0,$B21*E6,"") | F21: =IF($B21*F6>0,$B21*F6,"") | G21: =IF($B21*G6>0,$B21*G6,"") | H21: =IF($B21*H6>0,$B21*H6,"") | I21: =IF($B21*I6>0,$B21*I6,"") | J21: =IF($B21*J6>0,$B21*J6,"") | ... Y21: =IF($B21*Y6>0,$B21*Y6,"") | AB21: =IF($B21*AB6>0,$B21*AB6,"") | AC21: =IF($B21*AC6>0,$B21*AC6,"") | AD21: =IF($B21*AD6>0,$B21*AD6,"") | AE21: =IF($B21*AE6>0,$B21*AE6,"") | AF21: =IF($B21*AF6>0,$B21*AF6,"") | AG21: =IF($B21*AG6>0,$B21*AG6,"")
A22: 5 | B22: =Season_Coeff!N8 | C22: =IF($B22*C7>0,$B22*C7,"") | D22: =IF($B22*D7>0,$B22*D7,"") | E22: =IF($B22*E7>0,$B22*E7,"") | F22: =IF($B22*F7>0,$B22*F7,"") | G22: =IF($B22*G7>0,$B22*G7,"") | H22: =IF($B22*H7>0,$B22*H7,"") | I22: =IF($B22*I7>0,$B22*I7,"") | J22: =IF($B22*J7>0,$B22*J7,"") | ... Y22: =IF($B22*Y7>0,$B22*Y7,"") | AB22: =IF($B22*AB7>0,$B22*AB7,"") | AC22: =IF($B22*AC7>0,$B22*AC7,"") | AD22: =IF($B22*AD7>0,$B22*AD7,"") | AE22: =IF($B22*AE7>0,$B22*AE7,"") | AF22: =IF($B22*AF7>0,$B22*AF7,"") | AG22: =IF($B22*AG7>0,$B22*AG7,"")
A23: 6 | B23: =Season_Coeff!N9 | C23: =IF($B23*C8>0,$B23*C8,"") | D23: =IF($B23*D8>0,$B23*D8,"") | E23: =IF($B23*E8>0,$B23*E8,"") | F23: =IF($B23*F8>0,$B23*F8,"") | G23: =IF($B23*G8>0,$B23*G8,"") | H23: =IF($B23*H8>0,$B23*H8,"") | I23: =IF($B23*I8>0,$B23*I8,"") | J23: =IF($B23*J8>0,$B23*J8,"") | ... Y23: =IF($B23*Y8>0,$B23*Y8,"") | AB23: =IF($B23*AB8>0,$B23*AB8,"") | AC23: =IF($B23*AC8>0,$B23*AC8,"") | AD23: =IF($B23*AD8>0,$B23*AD8,"") | AE23: =IF($B23*AE8>0,$B23*AE8,"") | AF23: =IF($B23*AF8>0,$B23*AF8,"") | AG23: =IF($B23*AG8>0,$B23*AG8,"")
A24: 7 | B24: =Season_Coeff!N10 | C24: =IF($B24*C9>0,$B24*C9,"") | D24: =IF($B24*D9>0,$B24*D9,"") | E24: =IF($B24*E9>0,$B24*E9,"") | F24: =IF($B24*F9>0,$B24*F9,"") | G24: =IF($B24*G9>0,$B24*G9,"") | H24: =IF($B24*H9>0,$B24*H9,"") | I24: =IF($B24*I9>0,$B24*I9,"") | J24: =IF($B24*J9>0,$B24*J9,"") | ... Y24: =IF($B24*Y9>0,$B24*Y9,"") | AB24: =IF($B24*AB9>0,$B24*AB9,"") | AC24: =IF($B24*AC9>0,$B24*AC9,"") | AD24: =IF($B24*AD9>0,$B24*AD9,"") | AE24: =IF($B24*AE9>0,$B24*AE9,"") | AF24: =IF($B24*AF9>0,$B24*AF9,"") | AG24: =IF($B24*AG9>0,$B24*AG9,"")
A25: 8 | B25: =Season_Coeff!N11 | C25: =IF($B25*C10>0,$B25*C10,"") | D25: =IF($B25*D10>0,$B25*D10,"") | E25: =IF($B25*E10>0,$B25*E10,"") | F25: =IF($B25*F10>0,$B25*F10,"") | G25: =IF($B25*G10>0,$B25*G10,"") | H25: =IF($B25*H10>0,$B25*H10,"") | I25: =IF($B25*I10>0,$B25*I10,"") | J25: =IF($B25*J10>0,$B25*J10,"") | ... Y25: =IF($B25*Y10>0,$B25*Y10,"") | AB25: =IF($B25*AB10>0,$B25*AB10,"") | AC25: =IF($B25*AC10>0,$B25*AC10,"") | AD25: =IF($B25*AD10>0,$B25*AD10,"") | AE25: =IF($B25*AE10>0,$B25*AE10,"") | AF25: =IF($B25*AF10>0,$B25*AF10,"") | AG25: =IF($B25*AG10>0,$B25*AG10,"")
A26: 9 | B26: =Season_Coeff!N12 | C26: =IF($B26*C11>0,$B26*C11,"") | D26: =IF($B26*D11>0,$B26*D11,"") | E26: =IF($B26*E11>0,$B26*E11,"") | F26: =IF($B26*F11>0,$B26*F11,"") | G26: =IF($B26*G11>0,$B26*G11,"") | H26: =IF($B26*H11>0,$B26*H11,"") | I26: =IF($B26*I11>0,$B26*I11,"") | J26: =IF($B26*J11>0,$B26*J11,"") | ... Y26: =IF($B26*Y11>0,$B26*Y11,"") | AB26: =IF($B26*AB11>0,$B26*AB11,"") | AC26: =IF($B26*AC11>0,$B26*AC11,"") | AD26: =IF($B26*AD11>0,$B26*AD11,"") | AE26: =IF($B26*AE11>0,$B26*AE11,"") | AF26: =IF($B26*AF11>0,$B26*AF11,"") | AG26: =IF($B26*AG11>0,$B26*AG11,"")
A27: 10 | B27: =Season_Coeff!N13 | C27: =IF($B27*C12>0,$B27*C12,"") | D27: =IF($B27*D12>0,$B27*D12,"") | E27: =IF($B27*E12>0,$B27*E12,"") | F27: =IF($B27*F12>0,$B27*F12,"") | G27: =IF($B27*G12>0,$B27*G12,"") | H27: =IF($B27*H12>0,$B27*H12,"") | I27: =IF($B27*I12>0,$B27*I12,"") | J27: =IF($B27*J12>0,$B27*J12,"") | ... Y27: =IF($B27*Y12>0,$B27*Y12,"") | AB27: =IF($B27*AB12>0,$B27*AB12,"") | AC27: =IF($B27*AC12>0,$B27*AC12,"") | AD27: =IF($B27*AD12>0,$B27*AD12,"") | AE27: =IF($B27*AE12>0,$B27*AE12,"") | AF27: =IF($B27*AF12>0,$B27*AF12,"") | AG27: =IF($B27*AG12>0,$B27*AG12,"")
A28: 11 | B28: =Season_Coeff!N14 | C28: =IF($B28*C13>0,$B28*C13,"") | D28: =IF($B28*D13>0,$B28*D13,"") | E28: =IF($B28*E13>0,$B28*E13,"") | F28: =IF($B28*F13>0,$B28*F13,"") | G28: =IF($B28*G13>0,$B28*G13,"") | H28: =IF($B28*H13>0,$B28*H13,"") | I28: =IF($B28*I13>0,$B28*I13,"") | J28: =IF($B28*J13>0,$B28*J13,"") | ... Y28: =IF($B28*Y13>0,$B28*Y13,"") | AB28: =IF($B28*AB13>0,$B28*AB13,"") | AC28: =IF($B28*AC13>0,$B28*AC13,"") | AD28: =IF($B28*AD13>0,$B28*AD13,"") | AE28: =IF($B28*AE13>0,$B28*AE13,"") | AF28: =IF($B28*AF13>0,$B28*AF13,"") | AG28: =IF($B28*AG13>0,$B28*AG13,"")
A29: 12 | B29: =Season_Coeff!N15 | C29: =IF($B29*C14>0,$B29*C14,"") | D29: =IF($B29*D14>0,$B29*D14,"") | E29: =IF($B29*E14>0,$B29*E14,"") | F29: =IF($B29*F14>0,$B29*F14,"") | G29: =IF($B29*G14>0,$B29*G14,"") | H29: =IF($B29*H14>0,$B29*H14,"") | I29: =IF($B29*I14>0,$B29*I14,"") | J29: =IF($B29*J14>0,$B29*J14,"") | ... Y29: =IF($B29*Y14>0,$B29*Y14,"") | AB29: =IF($B29*AB14>0,$B29*AB14,"") | AC29: =IF($B29*AC14>0,$B29*AC14,"") | AD29: =IF($B29*AD14>0,$B29*AD14,"") | AE29: =IF($B29*AE14>0,$B29*AE14,"") | AF29: =IF($B29*AF14>0,$B29*AF14,"") | AG29: =IF($B29*AG14>0,$B29*AG14,"")
B30: Tot | C30: =SUM(C18:C29) | D30: =SUM(D18:D29) | E30: =SUM(E18:E29) | F30: =SUM(F18:F29) | G30: =SUM(G18:G29) | H30: =SUM(H18:H29) | I30: =SUM(I18:I29) | J30: =SUM(J18:J29) | ... Y30: =SUM(Y18:Y29) | AB30: =SUM(AB18:AB29) | AC30: =SUM(AC18:AC29) | AD30: =SUM(AD18:AD29) | AE30: =SUM(AE18:AE29) | AF30: =SUM(AF18:AF29) | AG30: =SUM(AG18:AG29)

Sheet BLAST-ClgRes
B1: Table B20-11. BLAST 3.0 Monthly and Total Sensible Cooling Loads (million Btu) | O1: Table B20-12. BLAST 3.0 Monthly and Total Sensible Cooling Loads (million Btu)
C2: L100AL | D2: L110AL | E2: L120AL | F2: L130AL | G2: L140AL | H2: L150AL | I2: L155AL | J2: L160AL | K2: L170AL | L2: L200AL | M2: L202AL | P2: L165AL | Q2: P100AC | R2: P105AC | S2: P110AC | T2: P140AC | U2: P150AC
A3: 1 | B3: Jan | C3: 0.07 | D3: 0.03 | E3: 0.08 | F3: 0 | G3: 0 | H3: 1.91 | I3: 1.55 | J3: 0.01 | K3: 0.03 | L3: 0.01 | M3: 0 | O3: Jan | P3: 0 | Q3: 0.62 | R3: 0.62 | S3: 2.17 | T3: 0 | U3: 0
A4: 2 | B4: Feb | C4: 0.38 | D4: 0.24 | E4: 0.41 | F4: 0.06 | G4: 0 | H4: 2.39 | I4: 1.58 | J4: 0.22 | K4: 0.22 | L4: 0.21 | M4: 0.1 | O4: Feb | P4: 0.07 | Q4: 0.17 | R4: 0.14 | S4: 1.42 | T4: 0 | U4: 0
A5: 3 | B5: Mar | C5: 1.44 | D5: 1.15 | E5: 1.46 | F5: 0.55 | G5: 0.07 | H5: 3.35 | I5: 1.69 | J5: 1.58 | K5: 1.01 | L5: 1.04 | M5: 0.69 | O5: Mar | P5: 1.01 | Q5: 0.03 | R5: 0 | S5: 1.09 | T5: 0 | U5: 0
A6: 4 | B6: Apr | C6: 2.18 | D6: 1.92 | E6: 2.16 | F6: 1.16 | G6: 0.36 | H6: 2.78 | I6: 1.16 | J6: 3.16 | K6: 1.6 | L6: 1.83 | M6: 1.42 | O6: Apr | P6: 2.38 | Q6: 0.25 | R6: 0 | S6: 0.91 | T6: 0 | U6: 0.16
A7: 5 | B7: May | C7: 5.85 | D7: 6.02 | E7: 5.55 | F7: 3.9 | G7: 2.14 | H7: 5.51 | I7: 4.3 | J7: 7.59 | K7: 4.76 | L7: 6.56 | M7: 5.81 | O7: May | P7: 6.53 | Q7: 0.48 | R7: 0.03 | S7: 1.27 | T7: 0 | U7: 0.48
A8: 6 | B8: Jun | C8: 9.43 | D8: 10.26 | E8: 8.72 | F8: 6.72 | G8: 4.61 | H8: 8.71 | I8: 7.85 | J8: 11.41 | K8: 8.1 | L8: 11.96 | M8: 10.99 | O8: Jun | P8: 10.26 | Q8: 2.05 | R8: 1.34 | S8: 2.55 | T8: 0.21 | U8: 2.42
A9: 7 | B9: Jul | C9: 12.16 | D9: 13.62 | E9: 11.15 | F9: 8.84 | G9: 6.57 | H9: 11.51 | I9: 10.69 | J9: 13.98 | K9: 10.67 | L9: 16.4 | M9: 15.44 | O9: Jul | P9: 12.92 | Q9: 3.1 | R9: 2.33 | S9: 3.47 | T9: 0.65 | U9: 3.46
A10: 8 | B10: Aug | C10: 10.87 | D10: 12.01 | E10: 10.02 | F10: 7.85 | G10: 5.65 | H10: 11.18 | I10: 9.19 | J10: 12.31 | K10: 9.41 | L10: 14.21 | M10: 13.26 | O10: Aug | P10: 11.28 | Q10: 3.7 | R10: 2.02 | S10: 4.15 | T10: 0.53 | U10: 3.25
A11: 9 | B11: Sep | C11: 7.76 | D11: 8.24 | E11: 7.33 | F11: 5.35 | G11: 3.32 | H11: 9.33 | I11: 7.08 | J11: 8.4 | K11: 6.51 | L11: 9.21 | M11: 8.44 | O11: Sep | P11: 7.4 | Q11: 3.59 | R11: 2 | S11: 4.4 | T11: 0.29 | U11: 2.01
A12: 10 | B12: Oct | C12: 3.92 | D12: 3.79 | E12: 3.84 | F12: 2.36 | G12: 0.8 | H12: 6.76 | I12: 5.43 | J12: 3.59 | K12: 3.13 | L12: 3.89 | M12: 3.24 | O12: Oct | P12: 2.75 | Q12: 3.29 | R12: 2.68 | S12: 4.64 | T12: 0 | U12: 0.65
A13: 11 | B13: Nov | C13: 0.6 | D13: 0.43 | E13: 0.63 | F13: 0.17 | G13: 0 | H13: 3.08 | I13: 2.55 | J13: 0.37 | K13: 0.39 | L13: 0.39 | M13: 0.22 | O13: Nov | P13: 0.17 | Q13: 0.58 | R13: 0.54 | S13: 2.33 | T13: 0 | U13: 0
A14: 12 | B14: Dec | C14: 0 | D14: 0 | E14: 0.01 | F14: 0 | G14: 0 | H14: 1.22 | I14: 1.02 | J14: 0 | K14: 0 | L14: 0 | M14: 0 | O14: Dec | P14: 0 | Q14: 0.25 | R14: 0.24 | S14: 1.79 | T14: 0 | U14: 0
B15: Tot | C15: 54.66 | D15: 57.7 | E15: 51.34 | F15: 36.95 | G15: 23.52 | H15: 67.72 | I15: 54.08 | J15: 62.61 | K15: 45.83 | L15: 65.7 | M15: 59.61 | O15: Tot | P15: 54.77 | Q15: 18.11 | R15: 11.95 | S15: 30.18 | T15: 1.67 | U15: 12.42
A16: Seasonal Values: | O16: Tier 2 Results
B17: Clg_Coeff | C17: =C2 | D17: =D2 | E17: =E2 | F17: =F2 | G17: =G2 | H17: =H2 | I17: =I2 | J17: =J2 | ... M17: =M2 | P17: =P2 | Q17: =Q2 | R17: =R2 | S17: =S2 | T17: =T2 | U17: =U2
A18: 1 | B18: =Season_Coeff!N19 | C18: =IF($B18*C3>0,$B18*C3,"") | D18: =IF($B18*D3>0,$B18*D3,"") | E18: =IF($B18*E3>0,$B18*E3,"") | F18: =IF($B18*F3>0,$B18*F3,"") | G18: =IF($B18*G3>0,$B18*G3,"") | H18: =IF($B18*H3>0,$B18*H3,"") | I18: =IF($B18*I3>0,$B18*I3,"") | J18: =IF($B18*J3>0,$B18*J3,"") | ... M18: =IF($B18*M3>0,$B18*M3,"") | P18: =IF($B18*P3>0,$B18*P3,"") | Q18: =IF($B18*Q3>0,$B18*Q3,"") | R18: =IF($B18*R3>0,$B18*R3,"") | S18: =IF($B18*S3>0,$B18*S3,"") | T18: =IF($B18*T3>0,$B18*T3,"") | U18: =IF($B18*U3>0,$B18*U3,"")
A19: 2 | B19: =Season_Coeff!N20 | C19: =IF($B19*C4>0,$B19*C4,"") | D19: =IF($B19*D4>0,$B19*D4,"") | E19: =IF($B19*E4>0,$B19*E4,"") | F19: =IF($B19*F4>0,$B19*F4,"") | G19: =IF($B19*G4>0,$B19*G4,"") | H19: =IF($B19*H4>0,$B19*H4,"") | I19: =IF($B19*I4>0,$B19*I4,"") | J19: =IF($B19*J4>0,$B19*J4,"") | ... M19: =IF($B19*M4>0,$B19*M4,"") | P19: =IF($B19*P4>0,$B19*P4,"") | Q19: =IF($B19*Q4>0,$B19*Q4,"") | R19: =IF($B19*R4>0,$B19*R4,"") | S19: =IF($B19*S4>0,$B19*S4,"") | T19: =IF($B19*T4>0,$B19*T4,"") | U19: =IF($B19*U4>0,$B19*U4,"")
A20: 3 | B20: =Season_Coeff!N21 | C20: =IF($B20*C5>0,$B20*C5,"") | D20: =IF($B20*D5>0,$B20*D5,"") | E20: =IF($B20*E5>0,$B20*E5,"") | F20: =IF($B20*F5>0,$B20*F5,"") | G20: =IF($B20*G5>0,$B20*G5,"") | H20: =IF($B20*H5>0,$B20*H5,"") | I20: =IF($B20*I5>0,$B20*I5,"") | J20: =IF($B20*J5>0,$B20*J5,"") | ... M20: =IF($B20*M5>0,$B20*M5,"") | P20: =IF($B20*P5>0,$B20*P5,"") | Q20: =IF($B20*Q5>0,$B20*Q5,"") | R20: =IF($B20*R5>0,$B20*R5,"") | S20: =IF($B20*S5>0,$B20*S5,"") | T20: =IF($B20*T5>0,$B20*T5,"") | U20: =IF($B20*U5>0,$B20*U5,"")
A21: 4 | B21: =Season_Coeff!N22 | C21: =IF($B21*C6>0,$B21*C6,"") | D21: =IF($B21*D6>0,$B21*D6,"") | E21: =IF($B21*E6>0,$B21*E6,"") | F21: =IF($B21*F6>0,$B21*F6,"") | G21: =IF($B21*G6>0,$B21*G6,"") | H21: =IF($B21*H6>0,$B21*H6,"") | I21: =IF($B21*I6>0,$B21*I6,"") | J21: =IF($B21*J6>0,$B21*J6,"") | ... M21: =IF($B21*M6>0,$B21*M6,"") | P21: =IF($B21*P6>0,$B21*P6,"") | Q21: =IF($B21*Q6>0,$B21*Q6,"") | R21: =IF($B21*R6>0,$B21*R6,"") | S21: =IF($B21*S6>0,$B21*S6,"") | T21: =IF($B21*T6>0,$B21*T6,"") | U21: =IF($B21*U6>0,$B21*U6,"")
A22: 5 | B22: =Season_Coeff!N23 | C22: =IF($B22*C7>0,$B22*C7,"") | D22: =IF($B22*D7>0,$B22*D7,"") | E22: =IF($B22*E7>0,$B22*E7,"") | F22: =IF($B22*F7>0,$B22*F7,"") | G22: =IF($B22*G7>0,$B22*G7,"") | H22: =IF($B22*H7>0,$B22*H7,"") | I22: =IF($B22*I7>0,$B22*I7,"") | J22: =IF($B22*J7>0,$B22*J7,"") | ... M22: =IF($B22*M7>0,$B22*M7,"") | P22: =IF($B22*P7>0,$B22*P7,"") | Q22: =IF($B22*Q7>0,$B22*Q7,"") | R22: =IF($B22*R7>0,$B22*R7,"") | S22: =IF($B22*S7>0,$B22*S7,"") | T22: =IF($B22*T7>0,$B22*T7,"") | U22: =IF($B22*U7>0,$B22*U7,"")
A23: 6 | B23: =Season_Coeff!N24 | C23: =IF($B23*C8>0,$B23*C8,"") | D23: =IF($B23*D8>0,$B23*D8,"") | E23: =IF($B23*E8>0,$B23*E8,"") | F23: =IF($B23*F8>0,$B23*F8,"") | G23: =IF($B23*G8>0,$B23*G8,"") | H23: =IF($B23*H8>0,$B23*H8,"") | I23: =IF($B23*I8>0,$B23*I8,"") | J23: =IF($B23*J8>0,$B23*J8,"") | ... M23: =IF($B23*M8>0,$B23*M8,"") | P23: =IF($B23*P8>0,$B23*P8,"") | Q23: =IF($B23*Q8>0,$B23*Q8,"") | R23: =IF($B23*R8>0,$B23*R8,"") | S23: =IF($B23*S8>0,$B23*S8,"") | T23: =IF($B23*T8>0,$B23*T8,"") | U23: =IF($B23*U8>0,$B23*U8,"")
A24: 7 | B24: =Season_Coeff!N25 | C24: =IF($B24*C9>0,$B24*C9,"") | D24: =IF($B24*D9>0,$B24*D9,"") | E24: =IF($B24*E9>0,$B24*E9,"") | F24: =IF($B24*F9>0,$B24*F9,"") | G24: =IF($B24*G9>0,$B24*G9,"") | H24: =IF($B24*H9>0,$B24*H9,"") | I24: =IF($B24*I9>0,$B24*I9,"") | J24: =IF($B24*J9>0,$B24*J9,"") | ... M24: =IF($B24*M9>0,$B24*M9,"") | P24: =IF($B24*P9>0,$B24*P9,"") | Q24: =IF($B24*Q9>0,$B24*Q9,"") | R24: =IF($B24*R9>0,$B24*R9,"") | S24: =IF($B24*S9>0,$B24*S9,"") | T24: =IF($B24*T9>0,$B24*T9,"") | U24: =IF($B24*U9>0,$B24*U9,"")
A25: 8 | B25: =Season_Coeff!N26 | C25: =IF($B25*C10>0,$B25*C10,"") | D25: =IF($B25*D10>0,$B25*D10,"") | E25: =IF($B25*E10>0,$B25*E10,"") | F25: =IF($B25*F10>0,$B25*F10,"") | G25: =IF($B25*G10>0,$B25*G10,"") | H25: =IF($B25*H10>0,$B25*H10,"") | I25: =IF($B25*I10>0,$B25*I10,"") | J25: =IF($B25*J10>0,$B25*J10,"") | ... M25: =IF($B25*M10>0,$B25*M10,"") | P25: =IF($B25*P10>0,$B25*P10,"") | Q25: =IF($B25*Q10>0,$B25*Q10,"") | R25: =IF($B25*R10>0,$B25*R10,"") | S25: =IF($B25*S10>0,$B25*S10,"") | T25: =IF($B25*T10>0,$B25*T10,"") | U25: =IF($B25*U10>0,$B25*U10,"")
A26: 9 | B26: =Season_Coeff!N27 | C26: =IF($B26*C11>0,$B26*C11,"") | D26: =IF($B26*D11>0,$B26*D11,"") | E26: =IF($B26*E11>0,$B26*E11,"") | F26: =IF($B26*F11>0,$B26*F11,"") | G26: =IF($B26*G11>0,$B26*G11,"") | H26: =IF($B26*H11>0,$B26*H11,"") | I26: =IF($B26*I11>0,$B26*I11,"") | J26: =IF($B26*J11>0,$B26*J11,"") | ... M26: =IF($B26*M11>0,$B26*M11,"") | P26: =IF($B26*P11>0,$B26*P11,"") | Q26: =IF($B26*Q11>0,$B26*Q11,"") | R26: =IF($B26*R11>0,$B26*R11,"") | S26: =IF($B26*S11>0,$B26*S11,"") | T26: =IF($B26*T11>0,$B26*T11,"") | U26: =IF($B26*U11>0,$B26*U11,"")
A27: 10 | B27: =Season_Coeff!N28 | C27: =IF($B27*C12>0,$B27*C12,"") | D27: =IF($B27*D12>0,$B27*D12,"") | E27: =IF($B27*E12>0,$B27*E12,"") | F27: =IF($B27*F12>0,$B27*F12,"") | G27: =IF($B27*G12>0,$B27*G12,"") | H27: =IF($B27*H12>0,$B27*H12,"") | I27: =IF($B27*I12>0,$B27*I12,"") | J27: =IF($B27*J12>0,$B27*J12,"") | ... M27: =IF($B27*M12>0,$B27*M12,"") | P27: =IF($B27*P12>0,$B27*P12,"") | Q27: =IF($B27*Q12>0,$B27*Q12,"") | R27: =IF($B27*R12>0,$B27*R12,"") | S27: =IF($B27*S12>0,$B27*S12,"") | T27: =IF($B27*T12>0,$B27*T12,"") | U27: =IF($B27*U12>0,$B27*U12,"")
A28: 11 | B28: =Season_Coeff!N29 | C28: =IF($B28*C13>0,$B28*C13,"") | D28: =IF($B28*D13>0,$B28*D13,"") | E28: =IF($B28*E13>0,$B28*E13,"") | F28: =IF($B28*F13>0,$B28*F13,"") | G28: =IF($B28*G13>0,$B28*G13,"") | H28: =IF($B28*H13>0,$B28*H13,"") | I28: =IF($B28*I13>0,$B28*I13,"") | J28: =IF($B28*J13>0,$B28*J13,"") | ... M28: =IF($B28*M13>0,$B28*M13,"") | P28: =IF($B28*P13>0,$B28*P13,"") | Q28: =IF($B28*Q13>0,$B28*Q13,"") | R28: =IF($B28*R13>0,$B28*R13,"") | S28: =IF($B28*S13>0,$B28*S13,"") | T28: =IF($B28*T13>0,$B28*T13,"") | U28: =IF($B28*U13>0,$B28*U13,"")
A29: 12 | B29: =Season_Coeff!N30 | C29: =IF($B29*C14>0,$B29*C14,"") | D29: =IF($B29*D14>0,$B29*D14,"") | E29: =IF($B29*E14>0,$B29*E14,"") | F29: =IF($B29*F14>0,$B29*F14,"") | G29: =IF($B29*G14>0,$B29*G14,"") | H29: =IF($B29*H14>0,$B29*H14,"") | I29: =IF($B29*I14>0,$B29*I14,"") | J29: =IF($B29*J14>0,$B29*J14,"") | ... M29: =IF($B29*M14>0,$B29*M14,"") | P29: =IF($B29*P14>0,$B29*P14,"") | Q29: =IF($B29*Q14>0,$B29*Q14,"") | R29: =IF($B29*R14>0,$B29*R14,"") | S29: =IF($B29*S14>0,$B29*S14,"") | T29: =IF($B29*T14>0,$B29*T14,"") | U29: =IF($B29*U14>0,$B29*U14,"")
B30: Tot | C30: =SUM(C18:C29) | D30: =SUM(D18:D29) | E30: =SUM(E18:E29) | F30: =SUM(F18:F29) | G30: =SUM(G18:G29) | H30: =SUM(H18:H29) | I30: =SUM(I18:I29) | J30: =SUM(J18:J29) | ... M30: =SUM(M18:M29) | P30: =SUM(P18:P29) | Q30: =SUM(Q18:Q29) | R30: =SUM(R18:R29) | S30: =SUM(S18:S29) | T30: =SUM(T18:T29) | U30: =SUM(U18:U29)

Sheet DOE-HtgRes
B1: Table B20-13. DOE-2.1E Monthly and Total Heating Loads (million Btu) | AA1: Table B20-14. DOE-2.1E Monthly and Total Heating Loads (million Btu)
C2: L100AC | D2: L110AC | E2: L120AC | F2: L130AC | G2: L140AC | H2: L150AC | I2: L155AC | J2: L160AC | K2: L170AC | L2: L200AC | M2: L202AC | N2: L302AC | O2: L302BC | P2: L304AC | Q2: L304BC | R2: L322A1 | S2: L322A2 | T2: L322B1 | U2: L322B2 | V2: L324A1 | W2: L324A2 | X2: L324B1 | Y2: L324B2 | AB2: L165AC | AC2: P100AC | AD2: P105AC | AE2: P110AC | AF2: P140AC | AG2: P150AC
A3: 1 | B3: Jan | C3: 10.58 | D3: 14.39 | E3: 8.46 | F3: 8.56 | G3: 8.67 | H3: 8.63 | I3: 8.73 | J3: 11.11 | K3: 12.3 | L3: 22.72 | M3: 23.56 | N3: 11.93 | O3: 11.37 | P3: 10.21 | Q3: 9.68 | R3: 15.43 | S3: 15.3 | T3: 15.03 | U3: 15.54 | V3: 11.18 | W3: 11.18 | X3: 10.28 | Y3: 9.92 | AA3: Jan | AB3: 12.14 | AC3: 2.04 | AD3: 2.12 | AE3: 3.71 | AF3: 5.14 | AG3: 4.94
A4: 2 | B4: Feb | C4: 9.04 | D4: 12.35 | E4: 7.23 | F4: 7.28 | G4: 7.46 | H4: 7.62 | I4: 7.8 | J4: 9.17 | K4: 10.58 | L4: 19.67 | M4: 20.46 | N4: 10.24 | O4: 9.88 | P4: 8.73 | Q4: 8.34 | R4: 13.3 | S4: 13.24 | T4: 13.08 | U4: 13.48 | V4: 9.56 | W4: 9.58 | X4: 8.87 | Y4: 8.6 | AA4: Feb | AB4: 10.14 | AC4: 1.9 | AD4: 2.01 | AE4: 3.44 | AF4: 4.45 | AG4: 4.17
A5: 3 | B5: Mar | C5: 8.32 | D5: 11.55 | E5: 6.59 | F5: 6.67 | G5: 7.01 | H5: 7.31 | I5: 7.8 | J5: 7.88 | K5: 9.96 | L5: 18.83 | M5: 19.74 | N5: 9.54 | O5: 8.95 | P5: 8.05 | Q5: 7.47 | R5: 12.53 | S5: 12.48 | T5: 11.92 | U5: 12.39 | V5: 8.8 | W5: 8.82 | X5: 7.8 | Y5: 7.71 | AA5: Mar | AB5: 8.89 | AC5: 1.8 | AD5: 2.32 | AE5: 3.27 | AF5: 4.09 | AG5: 3.42
A6: 4 | B6: Apr | C6: 4.79 | D6: 6.83 | E6: 3.67 | F6: 3.73 | G6: 3.98 | H6: 4.61 | I6: 5.12 | J6: 4.3 | K6: 6.11 | L6: 11.65 | M6: 12.33 | N6: 5.64 | O6: 4.85 | P6: 4.69 | Q6: 3.96 | R6: 7.47 | S6: 7.38 | T6: 6.12 | U6: 6.7 | V6: 5.05 | W6: 4.99 | X6: 3.72 | Y6: 4.21 | AA6: Apr | AB6: 4.83 | AC6: 1.05 | AD6: 1.73 | AE6: 1.98 | AF6: 2.06 | AG6: 1.47
A7: 5 | B7: May | C7: 2.27 | D7: 3.51 | E7: 1.6 | F7: 1.67 | G7: 1.76 | H7: 2.36 | I7: 2.67 | J7: 2.03 | K7: 3.33 | L7: 6.63 | M7: 7 | N7: 2.89 | O7: 1.91 | P7: 2.3 | Q7: 1.48 | R7: 3.9 | S7: 3.67 | T7: 2.09 | U7: 2.6 | V7: 2.37 | W7: 2.21 | X7: 0.99 | Y7: 1.6 | AA7: May | AB7: 2.36 | AC7: 0.33 | AD7: 0.63 | AE7: 0.81 | AF7: 0.58 | AG7: 0.34
A8: 6 | B8: Jun | C8: 0.66 | D8: 1.19 | E8: 0.4 | F8: 0.45 | G8: 0.48 | H8: 0.76 | I8: 0.85 | J8: 0.57 | K8: 1.19 | L8: 2.83 | M8: 3 | N8: 0.99 | O8: 0.41 | P8: 0.73 | Q8: 0.3 | R8: 1.36 | S8: 1.12 | T8: 0.38 | U8: 0.53 | V8: 0.67 | W8: 0.56 | X8: 0.12 | Y8: 0.33 | AA8: Jun | AB8: 0.7 | AC8: 0.05 | AD8: 0.11 | AE8: 0.19 | AF8: 0.09 | AG8: 0.03
A9: 7 | B9: Jul | C9: 0.06 | D9: 0.21 | E9: 0.02 | F9: 0.02 | G9: 0.02 | H9: 0.08 | I9: 0.1 | J9: 0.05 | K9: 0.28 | L9: 0.96 | M9: 1.04 | N9: 0.17 | O9: 0 | P9: 0.09 | Q9: 0 | R9: 0.26 | S9: 0.14 | T9: 0 | U9: 0 | V9: 0.05 | W9: 0.03 | X9: 0 | Y9: 0 | AA9: Jul | AB9: 0.08 | AC9: 0 | AD9: 0 | AE9: 0 | AF9: 0 | AG9: 0
A10: 8 | B10: Aug | C10: 0.13 | D10: 0.35 | E10: 0.05 | F10: 0.07 | G10: 0.05 | H10: 0.13 | I10: 0.19 | J10: 0.12 | K10: 0.45 | L10: 1.37 | M10: 1.46 | N10: 0.3 | O10: 0 | P10: 0.18 | Q10: 0 | R10: 0.43 | S10: 0.25 | T10: 0 | U10: 0.01 | V10: 0.12 | W10: 0.06 | X10: 0 | Y10: 0 | AA10: Aug | AB10: 0.16 | AC10: 0 | AD10: 0 | AE10: 0 | AF10: 0 | AG10: 0
A11: 9 | B11: Sep | C11: 1.17 | D11: 1.93 | E11: 0.71 | F11: 0.81 | G11: 0.81 | H11: 1 | I11: 1.3 | J11: 1.13 | K11: 1.91 | L11: 4.07 | M11: 4.26 | N11: 1.6 | O11: 0.68 | P11: 1.24 | Q11: 0.45 | R11: 2.14 | S11: 1.83 | T11: 0.36 | U11: 0.85 | V11: 1.18 | W11: 0.98 | X11: 0.06 | Y11: 0.51 | AA11: Sep | AB11: 1.3 | AC11: 0 | AD11: 0.01 | AE11: 0.14 | AF11: 0.06 | AG11: 0
A12: 10 | B12: Oct | C12: 3.33 | D12: 4.93 | E12: 2.36 | F12: 2.5 | G12: 2.63 | H12: 2.67 | I12: 3.05 | J12: 3.38 | K12: 4.55 | L12: 8.83 | M12: 9.2 | N12: 4.11 | O12: 3.01 | P12: 3.36 | Q12: 2.33 | R12: 5.41 | S12: 5.06 | T12: 3.32 | U12: 4.27 | V12: 3.47 | W12: 3.23 | X12: 1.57 | Y12: 2.51 | AA12: Oct | AB12: 3.75 | AC12: 0.22 | AD12: 0.29 | AE12: 0.7 | AF12: 1.02 | AG12: 0.48
A13: 11 | B13: Nov | C13: 7.63 | D13: 10.56 | E13: 6 | F13: 6.1 | G13: 6.39 | H13: 6.11 | I13: 6.38 | J13: 7.97 | K13: 9.22 | L13: 17.15 | M13: 17.88 | N13: 8.74 | O13: 8.19 | P13: 7.39 | Q13: 6.86 | R13: 11.41 | S13: 11.34 | T13: 10.95 | U13: 11.56 | V13: 8.07 | W13: 8.07 | X13: 7.13 | Y13: 7.01 | AA13: Nov | AB13: 8.89 | AC13: 0.86 | AD13: 1.02 | AE13: 2.34 | AF13: 3.66 | AG13: 3.04
A14: 12 | B14: Dec | C14: 10.02 | D14: 13.59 | E14: 8.01 | F14: 7.98 | G14: 7.99 | H14: 8.2 | I14: 8.31 | J14: 10.58 | K14: 11.77 | L14: 21.41 | M14: 22.13 | N14: 11.29 | O14: 10.87 | P14: 9.67 | Q14: 9.25 | R14: 14.62 | S14: 14.51 | T14: 14.47 | U14: 14.94 | V14: 10.59 | W14: 10.6 | X14: 9.84 | Y14: 9.48 | AA14: Dec | AB14: 11.49 | AC14: 1.77 | AD14: 1.86 | AE14: 3.59 | AF14: 4.67 | AG14: 4.69
B15: Tot | C15: 58 | D15: 81.36 | E15: 45.08 | F15: 45.82 | G15: 47.24 | H15: 49.47 | I15: 52.28 | J15: 58.28 | K15: 71.64 | L15: 136.12 | M15: 142.06 | N15: 67.43 | O15: 60.12 | P15: 56.62 | Q15: 50.11 | R15: 88.27 | S15: 86.33 | T15: 77.71 | U15: 82.87 | V15: 61.1 | W15: 60.31 | X15: 50.38 | Y15: 51.88 | AA15: Tot | AB15: 64.72 | AC15: 10.02 | AD15: 12.1 | AE15: 20.19 | AF15: 25.82 | AG15: 22.58
A16: Seasonal Values: | AA16: Tier 2 Results
B17: Htg_Coeff | C17: =C2 | D17: =D2 | E17: =E2 | F17: =F2 | G17: =G2 | H17: =H2 | I17: =I2 | J17: =J2 | ... Y17: =Y2 | AB17: =AB2 | AC17: =AC2 | AD17: =AD2 | AE17: =AE2 | AF17: =AF2 | AG17: =AG2
A18: 1 | B18: =Season_Coeff!N4 | C18: =IF($B18*C3>0,$B18*C3,"") | D18: =IF($B18*D3>0,$B18*D3,"") | E18: =IF($B18*E3>0,$B18*E3,"") | F18: =IF($B18*F3>0,$B18*F3,"") | G18: =IF($B18*G3>0,$B18*G3,"") | H18: =IF($B18*H3>0,$B18*H3,"") | I18: =IF($B18*I3>0,$B18*I3,"") | J18: =IF($B18*J3>0,$B18*J3,"") | ... Y18: =IF($B18*Y3>0,$B18*Y3,"") | AB18: =IF($B18*AB3>0,$B18*AB3,"") | AC18: =IF($B18*AC3>0,$B18*AC3,"") | AD18: =IF($B18*AD3>0,$B18*AD3,"") | AE18: =IF($B18*AE3>0,$B18*AE3,"") | AF18: =IF($B18*AF3>0,$B18*AF3,"") | AG18: =IF($B18*AG3>0,$B18*AG3,"")
A19: 2 | B19: =Season_Coeff!N5 | C19: =IF($B19*C4>0,$B19*C4,"") | D19: =IF($B19*D4>0,$B19*D4,"") | E19: =IF($B19*E4>0,$B19*E4,"") | F19: =IF($B19*F4>0,$B19*F4,"") | G19: =IF($B19*G4>0,$B19*G4,"") | H19: =IF($B19*H4>0,$B19*H4,"") | I19: =IF($B19*I4>0,$B19*I4,"") | J19: =IF($B19*J4>0,$B19*J4,"") | ... Y19: =IF($B19*Y4>0,$B19*Y4,"") | AB19: =IF($B19*AB4>0,$B19*AB4,"") | AC19: =IF($B19*AC4>0,$B19*AC4,"") | AD19: =IF($B19*AD4>0,$B19*AD4,"") | AE19: =IF($B19*AE4>0,$B19*AE4,"") | AF19: =IF($B19*AF4>0,$B19*AF4,"") | AG19: =IF($B19*AG4>0,$B19*AG4,"")
A20: 3 | B20: =Season_Coeff!N6 | C20: =IF($B20*C5>0,$B20*C5,"") | D20: =IF($B20*D5>0,$B20*D5,"") | E20: =IF($B20*E5>0,$B20*E5,"") | F20: =IF($B20*F5>0,$B20*F5,"") | G20: =IF($B20*G5>0,$B20*G5,"") | H20: =IF($B20*H5>0,$B20*H5,"") | I20: =IF($B20*I5>0,$B20*I5,"") | J20: =IF($B20*J5>0,$B20*J5,"") | ... Y20: =IF($B20*Y5>0,$B20*Y5,"") | AB20: =IF($B20*AB5>0,$B20*AB5,"") | AC20: =IF($B20*AC5>0,$B20*AC5,"") | AD20: =IF($B20*AD5>0,$B20*AD5,"") | AE20: =IF($B20*AE5>0,$B20*AE5,"") | AF20: =IF($B20*AF5>0,$B20*AF5,"") | AG20: =IF($B20*AG5>0,$B20*AG5,"")
A21: 4 | B21: =Season_Coeff!N7 | C21: =IF($B21*C6>0,$B21*C6,"") | D21: =IF($B21*D6>0,$B21*D6,"") | E21: =IF($B21*E6>0,$B21*E6,"") | F21: =IF($B21*F6>0,$B21*F6,"") | G21: =IF($B21*G6>0,$B21*G6,"") | H21: =IF($B21*H6>0,$B21*H6,"") | I21: =IF($B21*I6>0,$B21*I6,"") | J21: =IF($B21*J6>0,$B21*J6,"") | ... Y21: =IF($B21*Y6>0,$B21*Y6,"") | AB21: =IF($B21*AB6>0,$B21*AB6,"") | AC21: =IF($B21*AC6>0,$B21*AC6,"") | AD21: =IF($B21*AD6>0,$B21*AD6,"") | AE21: =IF($B21*AE6>0,$B21*AE6,"") | AF21: =IF($B21*AF6>0,$B21*AF6,"") | AG21: =IF($B21*AG6>0,$B21*AG6,"")
A22: 5 | B22: =Season_Coeff!N8 | C22: =IF($B22*C7>0,$B22*C7,"") | D22: =IF($B22*D7>0,$B22*D7,"") | E22: =IF($B22*E7>0,$B22*E7,"") | F22: =IF($B22*F7>0,$B22*F7,"") | G22: =IF($B22*G7>0,$B22*G7,"") | H22: =IF($B22*H7>0,$B22*H7,"") | I22: =IF($B22*I7>0,$B22*I7,"") | J22: =IF($B22*J7>0,$B22*J7,"") | ... Y22: =IF($B22*Y7>0,$B22*Y7,"") | AB22: =IF($B22*AB7>0,$B22*AB7,"") | AC22: =IF($B22*AC7>0,$B22*AC7,"") | AD22: =IF($B22*AD7>0,$B22*AD7,"") | AE22: =IF($B22*AE7>0,$B22*AE7,"") | AF22: =IF($B22*AF7>0,$B22*AF7,"") | AG22: =IF($B22*AG7>0,$B22*AG7,"")
A23: 6 | B23: =Season_Coeff!N9 | C23: =IF($B23*C8>0,$B23*C8,"") | D23: =IF($B23*D8>0,$B23*D8,"") | E23: =IF($B23*E8>0,$B23*E8,"") | F23: =IF($B23*F8>0,$B23*F8,"") | G23: =IF($B23*G8>0,$B23*G8,"") | H23: =IF($B23*H8>0,$B23*H8,"") | I23: =IF($B23*I8>0,$B23*I8,"") | J23: =IF($B23*J8>0,$B23*J8,"") | ... Y23: =IF($B23*Y8>0,$B23*Y8,"") | AB23: =IF($B23*AB8>0,$B23*AB8,"") | AC23: =IF($B23*AC8>0,$B23*AC8,"") | AD23: =IF($B23*AD8>0,$B23*AD8,"") | AE23: =IF($B23*AE8>0,$B23*AE8,"") | AF23: =IF($B23*AF8>0,$B23*AF8,"") | AG23: =IF($B23*AG8>0,$B23*AG8,"")
A24: 7 | B24: =Season_Coeff!N10 | C24: =IF($B24*C9>0,$B24*C9,"") | D24: =IF($B24*D9>0,$B24*D9,"") | E24: =IF($B24*E9>0,$B24*E9,"") | F24: =IF($B24*F9>0,$B24*F9,"") | G24: =IF($B24*G9>0,$B24*G9,"") | H24: =IF($B24*H9>0,$B24*H9,"") | I24: =IF($B24*I9>0,$B24*I9,"") | J24: =IF($B24*J9>0,$B24*J9,"") | ... Y24: =IF($B24*Y9>0,$B24*Y9,"") | AB24: =IF($B24*AB9>0,$B24*AB9,"") | AC24: =IF($B24*AC9>0,$B24*AC9,"") | AD24: =IF($B24*AD9>0,$B24*AD9,"") | AE24: =IF($B24*AE9>0,$B24*AE9,"") | AF24: =IF($B24*AF9>0,$B24*AF9,"") | AG24: =IF($B24*AG9>0,$B24*AG9,"")
A25: 8 | B25: =Season_Coeff!N11 | C25: =IF($B25*C10>0,$B25*C10,"") | D25: =IF($B25*D10>0,$B25*D10,"") | E25: =IF($B25*E10>0,$B25*E10,"") | F25: =IF($B25*F10>0,$B25*F10,"") | G25: =IF($B25*G10>0,$B25*G10,"") | H25: =IF($B25*H10>0,$B25*H10,"") | I25: =IF($B25*I10>0,$B25*I10,"") | J25: =IF($B25*J10>0,$B25*J10,"") | ... Y25: =IF($B25*Y10>0,$B25*Y10,"") | AB25: =IF($B25*AB10>0,$B25*AB10,"") | AC25: =IF($B25*AC10>0,$B25*AC10,"") | AD25: =IF($B25*AD10>0,$B25*AD10,"") | AE25: =IF($B25*AE10>0,$B25*AE10,"") | AF25: =IF($B25*AF10>0,$B25*AF10,"") | AG25: =IF($B25*AG10>0,$B25*AG10,"")
A26: 9 | B26: =Season_Coeff!N12 | C26: =IF($B26*C11>0,$B26*C11,"") | D26: =IF($B26*D11>0,$B26*D11,"") | E26: =IF($B26*E11>0,$B26*E11,"") | F26: =IF($B26*F11>0,$B26*F11,"") | G26: =IF($B26*G11>0,$B26*G11,"") | H26: =IF($B26*H11>0,$B26*H11,"") | I26: =IF($B26*I11>0,$B26*I11,"") | J26: =IF($B26*J11>0,$B26*J11,"") | ... Y26: =IF($B26*Y11>0,$B26*Y11,"") | AB26: =IF($B26*AB11>0,$B26*AB11,"") | AC26: =IF($B26*AC11>0,$B26*AC11,"") | AD26: =IF($B26*AD11>0,$B26*AD11,"") | AE26: =IF($B26*AE11>0,$B26*AE11,"") | AF26: =IF($B26*AF11>0,$B26*AF11,"") | AG26: =IF($B26*AG11>0,$B26*AG11,"")
A27: 10 | B27: =Season_Coeff!N13 | C27: =IF($B27*C12>0,$B27*C12,"") | D27: =IF($B27*D12>0,$B27*D12,"") | E27: =IF($B27*E12>0,$B27*E12,"") | F27: =IF($B27*F12>0,$B27*F12,"") | G27: =IF($B27*G12>0,$B27*G12,"") | H27: =IF($B27*H12>0,$B27*H12,"") | I27: =IF($B27*I12>0,$B27*I12,"") | J27: =IF($B27*J12>0,$B27*J12,"") | ... Y27: =IF($B27*Y12>0,$B27*Y12,"") | AB27: =IF($B27*AB12>0,$B27*AB12,"") | AC27: =IF($B27*AC12>0,$B27*AC12,"") | AD27: =IF($B27*AD12>0,$B27*AD12,"") | AE27: =IF($B27*AE12>0,$B27*AE12,"") | AF27: =IF($B27*AF12>0,$B27*AF12,"") | AG27: =IF($B27*AG12>0,$B27*AG12,"")
A28: 11 | B28: =Season_Coeff!N14 | C28: =IF($B28*C13>0,$B28*C13,"") | D28: =IF($B28*D13>0,$B28*D13,"") | E28: =IF($B28*E13>0,$B28*E13,"") | F28: =IF($B28*F13>0,$B28*F13,"") | G28: =IF($B28*G13>0,$B28*G13,"") | H28: =IF($B28*H13>0,$B28*H13,"") | I28: =IF($B28*I13>0,$B28*I13,"") | J28: =IF($B28*J13>0,$B28*J13,"") | ... Y28: =IF($B28*Y13>0,$B28*Y13,"") | AB28: =IF($B28*AB13>0,$B28*AB13,"") | AC28: =IF($B28*AC13>0,$B28*AC13,"") | AD28: =IF($B28*AD13>0,$B28*AD13,"") | AE28: =IF($B28*AE13>0,$B28*AE13,"") | AF28: =IF($B28*AF13>0,$B28*AF13,"") | AG28: =IF($B28*AG13>0,$B28*AG13,"")
A29: 12 | B29: =Season_Coeff!N15 | C29: =IF($B29*C14>0,$B29*C14,"") | D29: =IF($B29*D14>0,$B29*D14,"") | E29: =IF($B29*E14>0,$B29*E14,"") | F29: =IF($B29*F14>0,$B29*F14,"") | G29: =IF($B29*G14>0,$B29*G14,"") | H29: =IF($B29*H14>0,$B29*H14,"") | I29: =IF($B29*I14>0,$B29*I14,"") | J29: =IF($B29*J14>0,$B29*J14,"") | ... Y29: =IF($B29*Y14>0,$B29*Y14,"") | AB29: =IF($B29*AB14>0,$B29*AB14,"") | AC29: =IF($B29*AC14>0,$B29*AC14,"") | AD29: =IF($B29*AD14>0,$B29*AD14,"") | AE29: =IF($B29*AE14>0,$B29*AE14,"") | AF29: =IF($B29*AF14>0,$B29*AF14,"") | AG29: =IF($B29*AG14>0,$B29*AG14,"")
B30: Tot | C30: =SUM(C18:C29) | D30: =SUM(D18:D29) | E30: =SUM(E18:E29) | F30: =SUM(F18:F29) | G30: =SUM(G18:G29) | H30: =SUM(H18:H29) | I30: =SUM(I18:I29) | J30: =SUM(J18:J29) | ... Y30: =SUM(Y18:Y29) | AB30: =SUM(AB18:AB29) | AC30: =SUM(AC18:AC29) | AD30: =SUM(AD18:AD29) | AE30: =SUM(AE18:AE29) | AF30: =SUM(AF18:AF29) | AG30: =SUM(AG18:AG29)

Sheet DOE-ClgRes
B1: Table B20-15. DOE-2.1E Monthly and Total Sensible Cooling Loads (million Btu) | O1: Table B20-16. DOE-2.1E Monthly and Total Sensible Cooling Loads (million Btu)
C2: L100AL | D2: L110AL | E2: L120AL | F2: L130AL | G2: L140AL | H2: L150AL | I2: L155AL | J2: L160AL | K2: L170AL | L2: L200AL | M2: L202AL | P2: L165AL | Q2: P100AC | R2: P105AC | S2: P110AC | T2: P140AC | U2: P150AC
A3: 1 | B3: Jan | C3: 0.24 | D3: 0.1 | E3: 0.24 | F3: 0.02 | G3: 0 | H3: 2.94 | I3: 2.5 | J3: 0.05 | K3: 0.1 | L3: 0.08 | M3: 0 | O3: Jan | P3: 0 | Q3: 1.19 | R3: 1.12 | S3: 2.8 | T3: 0 | U3: 0
A4: 2 | B4: Feb | C4: 0.83 | D4: 0.54 | E4: 0.83 | F4: 0.19 | G4: 0 | H4: 3.59 | I4: 2.81 | J4: 0.5 | K4: 0.49 | L4: 0.54 | M4: 0.23 | O4: Feb | P4: 0.11 | Q4: 0.47 | R4: 0.39 | S4: 2.13 | T4: 0 | U4: 0
A5: 3 | B5: Mar | C5: 2.24 | D5: 1.8 | E5: 2.13 | F5: 0.9 | G5: 0.13 | H5: 4.55 | I5: 3.01 | J5: 2.41 | K5: 1.56 | L5: 1.79 | M5: 0.99 | O5: Mar | P5: 1.1 | Q5: 0.21 | R5: 0.03 | S5: 1.54 | T5: 0 | U5: 0
A6: 4 | B6: Apr | C6: 2.98 | D6: 2.62 | E6: 2.83 | F6: 1.57 | G6: 0.54 | H6: 3.82 | I6: 2.03 | J6: 4.16 | K6: 2.15 | L6: 2.59 | M6: 1.72 | O6: Apr | P6: 2.48 | Q6: 0.43 | R6: 0.13 | S6: 1.34 | T6: 0 | U6: 0.27
A7: 5 | B7: May | C7: 6.5 | D7: 6.71 | E7: 6.03 | F7: 4.39 | G7: 2.55 | H7: 6.01 | I7: 4.46 | J7: 8.51 | K7: 5.13 | L7: 7.46 | M7: 6.13 | O7: May | P7: 6.39 | Q7: 0.73 | R7: 0.1 | S7: 1.56 | T7: 0 | U7: 0.81
A8: 6 | B8: Jun | C8: 9.88 | D8: 10.84 | E8: 8.97 | F8: 7.26 | G8: 5.14 | H8: 8.74 | I8: 7.79 | J8: 11.98 | K8: 8.21 | L8: 12.71 | M8: 11.1 | O8: Jun | P8: 9.74 | Q8: 2.18 | R8: 1.4 | S8: 2.69 | T8: 0.44 | U8: 2.75
A9: 7 | B9: Jul | C9: 12.64 | D9: 14.29 | E9: 11.42 | F9: 9.49 | G9: 7.15 | H9: 11.76 | I9: 10.61 | J9: 14.52 | K9: 10.75 | L9: 17.18 | M9: 15.68 | O9: Jul | P9: 12.32 | Q9: 3.51 | R9: 2.45 | S9: 3.86 | T9: 1.09 | U9: 3.92
A10: 8 | B10: Aug | C10: 11.41 | D10: 12.71 | E10: 10.37 | F10: 8.47 | G10: 6.19 | H10: 11.58 | I10: 9.15 | J10: 12.92 | K10: 9.58 | L10: 15.03 | M10: 13.48 | O10: Aug | P10: 10.79 | Q10: 4.14 | R10: 2.09 | S10: 4.55 | T10: 0.91 | U10: 3.71
A11: 9 | B11: Sep | C11: 8.46 | D11: 9.03 | E11: 7.89 | F11: 5.91 | G11: 3.76 | H11: 10.35 | I11: 6.69 | J11: 9 | K11: 6.92 | L11: 10.2 | M11: 8.91 | O11: Sep | P11: 7.14 | Q11: 4.31 | R11: 1.91 | S11: 5.15 | T11: 0.4 | U11: 2.56
A12: 10 | B12: Oct | C12: 4.57 | D12: 4.47 | E12: 4.37 | F12: 2.76 | G12: 1.08 | H12: 7.73 | I12: 5.26 | J12: 4.15 | K12: 3.58 | L12: 4.79 | M12: 3.67 | O12: Oct | P12: 2.66 | Q12: 3.94 | R12: 2.4 | S12: 5.31 | T12: 0 | U12: 1.01
A13: 11 | B13: Nov | C13: 0.99 | D13: 0.7 | E13: 0.99 | F13: 0.29 | G13: 0 | H13: 4.13 | I13: 3.04 | J13: 0.49 | K13: 0.6 | L13: 0.72 | M13: 0.33 | O13: Nov | P13: 0.14 | Q13: 1.28 | R13: 1.03 | S13: 3.11 | T13: 0 | U13: 0
A14: 12 | B14: Dec | C14: 0.06 | D14: 0.01 | E14: 0.07 | F14: 0 | G14: 0 | H14: 2.15 | I14: 1.71 | J14: 0 | K14: 0.01 | L14: 0.01 | M14: 0 | O14: Dec | P14: 0 | Q14: 0.62 | R14: 0.56 | S14: 2.44 | T14: 0 | U14: 0
B15: Tot | C15: 60.8 | D15: 63.83 | E15: 56.14 | F15: 41.26 | G15: 26.54 | H15: 77.35 | I15: 59.06 | J15: 68.68 | K15: 49.06 | L15: 73.1 | M15: 62.24 | O15: Tot | P15: 52.88 | Q15: 23.03 | R15: 13.63 | S15: 36.49 | T15: 2.84 | U15: 15.03
A16: Seasonal Values: | O16: Tier 2 Results
B17: Clg_Coeff | C17: =C2 | D17: =D2 | E17: =E2 | F17: =F2 | G17: =G2 | H17: =H2 | I17: =I2 | J17: =J2 | ... M17: =M2 | P17: =P2 | Q17: =Q2 | R17: =R2 | S17: =S2 | T17: =T2 | U17: =U2
A18: 1 | B18: =Season_Coeff!N19 | C18: =IF($B18*C3>0,$B18*C3,"") | D18: =IF($B18*D3>0,$B18*D3,"") | E18: =IF($B18*E3>0,$B18*E3,"") | F18: =IF($B18*F3>0,$B18*F3,"") | G18: =IF($B18*G3>0,$B18*G3,"") | H18: =IF($B18*H3>0,$B18*H3,"") | I18: =IF($B18*I3>0,$B18*I3,"") | J18: =IF($B18*J3>0,$B18*J3,"") | ... M18: =IF($B18*M3>0,$B18*M3,"") | P18: =IF($B18*P3>0,$B18*P3,"") | Q18: =IF($B18*Q3>0,$B18*Q3,"") | R18: =IF($B18*R3>0,$B18*R3,"") | S18: =IF($B18*S3>0,$B18*S3,"") | T18: =IF($B18*T3>0,$B18*T3,"") | U18: =IF($B18*U3>0,$B18*U3,"")
A19: 2 | B19: =Season_Coeff!N20 | C19: =IF($B19*C4>0,$B19*C4,"") | D19: =IF($B19*D4>0,$B19*D4,"") | E19: =IF($B19*E4>0,$B19*E4,"") | F19: =IF($B19*F4>0,$B19*F4,"") | G19: =IF($B19*G4>0,$B19*G4,"") | H19: =IF($B19*H4>0,$B19*H4,"") | I19: =IF($B19*I4>0,$B19*I4,"") | J19: =IF($B19*J4>0,$B19*J4,"") | ... M19: =IF($B19*M4>0,$B19*M4,"") | P19: =IF($B19*P4>0,$B19*P4,"") | Q19: =IF($B19*Q4>0,$B19*Q4,"") | R19: =IF($B19*R4>0,$B19*R4,"") | S19: =IF($B19*S4>0,$B19*S4,"") | T19: =IF($B19*T4>0,$B19*T4,"") | U19: =IF($B19*U4>0,$B19*U4,"")
A20: 3 | B20: =Season_Coeff!N21 | C20: =IF($B20*C5>0,$B20*C5,"") | D20: =IF($B20*D5>0,$B20*D5,"") | E20: =IF($B20*E5>0,$B20*E5,"") | F20: =IF($B20*F5>0,$B20*F5,"") | G20: =IF($B20*G5>0,$B20*G5,"") | H20: =IF($B20*H5>0,$B20*H5,"") | I20: =IF($B20*I5>0,$B20*I5,"") | J20: =IF($B20*J5>0,$B20*J5,"") | ... M20: =IF($B20*M5>0,$B20*M5,"") | P20: =IF($B20*P5>0,$B20*P5,"") | Q20: =IF($B20*Q5>0,$B20*Q5,"") | R20: =IF($B20*R5>0,$B20*R5,"") | S20: =IF($B20*S5>0,$B20*S5,"") | T20: =IF($B20*T5>0,$B20*T5,"") | U20: =IF($B20*U5>0,$B20*U5,"")
A21: 4 | B21: =Season_Coeff!N22 | C21: =IF($B21*C6>0,$B21*C6,"") | D21: =IF($B21*D6>0,$B21*D6,"") | E21: =IF($B21*E6>0,$B21*E6,"") | F21: =IF($B21*F6>0,$B21*F6,"") | G21: =IF($B21*G6>0,$B21*G6,"") | H21: =IF($B21*H6>0,$B21*H6,"") | I21: =IF($B21*I6>0,$B21*I6,"") | J21: =IF($B21*J6>0,$B21*J6,"") | ... M21: =IF($B21*M6>0,$B21*M6,"") | P21: =IF($B21*P6>0,$B21*P6,"") | Q21: =IF($B21*Q6>0,$B21*Q6,"") | R21: =IF($B21*R6>0,$B21*R6,"") | S21: =IF($B21*S6>0,$B21*S6,"") | T21: =IF($B21*T6>0,$B21*T6,"") | U21: =IF($B21*U6>0,$B21*U6,"")
A22: 5 | B22: =Season_Coeff!N23 | C22: =IF($B22*C7>0,$B22*C7,"") | D22: =IF($B22*D7>0,$B22*D7,"") | E22: =IF($B22*E7>0,$B22*E7,"") | F22: =IF($B22*F7>0,$B22*F7,"") | G22: =IF($B22*G7>0,$B22*G7,"") | H22: =IF($B22*H7>0,$B22*H7,"") | I22: =IF($B22*I7>0,$B22*I7,"") | J22: =IF($B22*J7>0,$B22*J7,"") | ... M22: =IF($B22*M7>0,$B22*M7,"") | P22: =IF($B22*P7>0,$B22*P7,"") | Q22: =IF($B22*Q7>0,$B22*Q7,"") | R22: =IF($B22*R7>0,$B22*R7,"") | S22: =IF($B22*S7>0,$B22*S7,"") | T22: =IF($B22*T7>0,$B22*T7,"") | U22: =IF($B22*U7>0,$B22*U7,"")
A23: 6 | B23: =Season_Coeff!N24 | C23: =IF($B23*C8>0,$B23*C8,"") | D23: =IF($B23*D8>0,$B23*D8,"") | E23: =IF($B23*E8>0,$B23*E8,"") | F23: =IF($B23*F8>0,$B23*F8,"") | G23: =IF($B23*G8>0,$B23*G8,"") | H23: =IF($B23*H8>0,$B23*H8,"") | I23: =IF($B23*I8>0,$B23*I8,"") | J23: =IF($B23*J8>0,$B23*J8,"") | ... M23: =IF($B23*M8>0,$B23*M8,"") | P23: =IF($B23*P8>0,$B23*P8,"") | Q23: =IF($B23*Q8>0,$B23*Q8,"") | R23: =IF($B23*R8>0,$B23*R8,"") | S23: =IF($B23*S8>0,$B23*S8,"") | T23: =IF($B23*T8>0,$B23*T8,"") | U23: =IF($B23*U8>0,$B23*U8,"")
A24: 7 | B24: =Season_Coeff!N25 | C24: =IF($B24*C9>0,$B24*C9,"") | D24: =IF($B24*D9>0,$B24*D9,"") | E24: =IF($B24*E9>0,$B24*E9,"") | F24: =IF($B24*F9>0,$B24*F9,"") | G24: =IF($B24*G9>0,$B24*G9,"") | H24: =IF($B24*H9>0,$B24*H9,"") | I24: =IF($B24*I9>0,$B24*I9,"") | J24: =IF($B24*J9>0,$B24*J9,"") | ... M24: =IF($B24*M9>0,$B24*M9,"") | P24: =IF($B24*P9>0,$B24*P9,"") | Q24: =IF($B24*Q9>0,$B24*Q9,"") | R24: =IF($B24*R9>0,$B24*R9,"") | S24: =IF($B24*S9>0,$B24*S9,"") | T24: =IF($B24*T9>0,$B24*T9,"") | U24: =IF($B24*U9>0,$B24*U9,"")
A25: 8 | B25: =Season_Coeff!N26 | C25: =IF($B25*C10>0,$B25*C10,"") | D25: =IF($B25*D10>0,$B25*D10,"") | E25: =IF($B25*E10>0,$B25*E10,"") | F25: =IF($B25*F10>0,$B25*F10,"") | G25: =IF($B25*G10>0,$B25*G10,"") | H25: =IF($B25*H10>0,$B25*H10,"") | I25: =IF($B25*I10>0,$B25*I10,"") | J25: =IF($B25*J10>0,$B25*J10,"") | ... M25: =IF($B25*M10>0,$B25*M10,"") | P25: =IF($B25*P10>0,$B25*P10,"") | Q25: =IF($B25*Q10>0,$B25*Q10,"") | R25: =IF($B25*R10>0,$B25*R10,"") | S25: =IF($B25*S10>0,$B25*S10,"") | T25: =IF($B25*T10>0,$B25*T10,"") | U25: =IF($B25*U10>0,$B25*U10,"")
A26: 9 | B26: =Season_Coeff!N27 | C26: =IF($B26*C11>0,$B26*C11,"") | D26: =IF($B26*D11>0,$B26*D11,"") | E26: =IF($B26*E11>0,$B26*E11,"") | F26: =IF($B26*F11>0,$B26*F11,"") | G26: =IF($B26*G11>0,$B26*G11,"") | H26: =IF($B26*H11>0,$B26*H11,"") | I26: =IF($B26*I11>0,$B26*I11,"") | J26: =IF($B26*J11>0,$B26*J11,"") | ... M26: =IF($B26*M11>0,$B26*M11,"") | P26: =IF($B26*P11>0,$B26*P11,"") | Q26: =IF($B26*Q11>0,$B26*Q11,"") | R26: =IF($B26*R11>0,$B26*R11,"") | S26: =IF($B26*S11>0,$B26*S11,"") | T26: =IF($B26*T11>0,$B26*T11,"") | U26: =IF($B26*U11>0,$B26*U11,"")
A27: 10 | B27: =Season_Coeff!N28 | C27: =IF($B27*C12>0,$B27*C12,"") | D27: =IF($B27*D12>0,$B27*D12,"") | E27: =IF($B27*E12>0,$B27*E12,"") | F27: =IF($B27*F12>0,$B27*F12,"") | G27: =IF($B27*G12>0,$B27*G12,"") | H27: =IF($B27*H12>0,$B27*H12,"") | I27: =IF($B27*I12>0,$B27*I12,"") | J27: =IF($B27*J12>0,$B27*J12,"") | ... M27: =IF($B27*M12>0,$B27*M12,"") | P27: =IF($B27*P12>0,$B27*P12,"") | Q27: =IF($B27*Q12>0,$B27*Q12,"") | R27: =IF($B27*R12>0,$B27*R12,"") | S27: =IF($B27*S12>0,$B27*S12,"") | T27: =IF($B27*T12>0,$B27*T12,"") | U27: =IF($B27*U12>0,$B27*U12,"")
A28: 11 | B28: =Season_Coeff!N29 | C28: =IF($B28*C13>0,$B28*C13,"") | D28: =IF($B28*D13>0,$B28*D13,"") | E28: =IF($B28*E13>0,$B28*E13,"") | F28: =IF($B28*F13>0,$B28*F13,"") | G28: =IF($B28*G13>0,$B28*G13,"") | H28: =IF($B28*H13>0,$B28*H13,"") | I28: =IF($B28*I13>0,$B28*I13,"") | J28: =IF($B28*J13>0,$B28*J13,"") | ... M28: =IF($B28*M13>0,$B28*M13,"") | P28: =IF($B28*P13>0,$B28*P13,"") | Q28: =IF($B28*Q13>0,$B28*Q13,"") | R28: =IF($B28*R13>0,$B28*R13,"") | S28: =IF($B28*S13>0,$B28*S13,"") | T28: =IF($B28*T13>0,$B28*T13,"") | U28: =IF($B28*U13>0,$B28*U13,"")
A29: 12 | B29: =Season_Coeff!N30 | C29: =IF($B29*C14>0,$B29*C14,"") | D29: =IF($B29*D14>0,$B29*D14,"") | E29: =IF($B29*E14>0,$B29*E14,"") | F29: =IF($B29*F14>0,$B29*F14,"") | G29: =IF($B29*G14>0,$B29*G14,"") | H29: =IF($B29*H14>0,$B29*H14,"") | I29: =IF($B29*I14>0,$B29*I14,"") | J29: =IF($B29*J14>0,$B29*J14,"") | ... M29: =IF($B29*M14>0,$B29*M14,"") | P29: =IF($B29*P14>0,$B29*P14,"") | Q29: =IF($B29*Q14>0,$B29*Q14,"") | R29: =IF($B29*R14>0,$B29*R14,"") | S29: =IF($B29*S14>0,$B29*S14,"") | T29: =IF($B29*T14>0,$B29*T14,"") | U29: =IF($B29*U14>0,$B29*U14,"")
B30: Tot | C30: =SUM(C18:C29) | D30: =SUM(D18:D29) | E30: =SUM(E18:E29) | F30: =SUM(F18:F29) | G30: =SUM(G18:G29) | H30: =SUM(H18:H29) | I30: =SUM(I18:I29) | J30: =SUM(J18:J29) | ... M30: =SUM(M18:M29) | P30: =SUM(P18:P29) | Q30: =SUM(Q18:Q29) | R30: =SUM(R18:R29) | S30: =SUM(S18:S29) | T30: =SUM(T18:T29) | U30: =SUM(U18:U29)

Sheet SRES-HtgRes
B1: Table B20-17. SERIRES/SUNCODE 5.7 Monthly and Total Heating Loads (million Btu) | AA1: Table B20-18. SERIRES/SUNCODE 5.7 Monthly and Total Heating Loads (million Btu)
C2: L100AC | D2: L110AC | E2: L120AC | F2: L130AC | G2: L140AC | H2: L150AC | I2: L155AC | J2: L160AC | K2: L170AC | L2: L200AC | M2: L202AC | N2: L302AC | O2: L302BC | P2: L304AC | Q2: L304BC | R2: L322A1 | S2: L322A2 | T2: L322B1 | U2: L322B2 | V2: L324A1 | W2: L324A2 | X2: L324B1 | Y2: L324B2 | AB2: L165AC | AC2: P100AC | AD2: P105AC | AE2: P110AC | AF2: P140AC | AG2: P150AC
A3: 1 | B3: Jan | C3: 13.38 | D3: 17.31 | E3: 10.94 | F3: 9.46 | G3: 9.55 | H3: 11.39 | I3: 11.5 | J3: 14.11 | K3: 15 | L3: 28.72 | M3: 29.22 | N3: 14.96 | O3: 13.92 | P3: 12.72 | Q3: 11.94 | R3: 19.07 | S3: 19.23 | T3: 17.76 | U3: 17.78 | V3: 13.59 | W3: 13.68 | X3: 12.23 | Y3: 12.41 | AA3: Jan | AB3: 14.9 | AC3: 2.97 | AD3: 3.01 | AE3: 4.56 | AF3: 5.69 | AG3: 6.09
A4: 2 | B4: Feb | C4: 11.34 | D4: 14.77 | E4: 9.26 | F4: 8.05 | G4: 8.25 | H4: 9.89 | I4: 10.17 | J4: 11.67 | K4: 12.8 | L4: 24.72 | M4: 25.25 | N4: 12.73 | O4: 12.31 | P4: 10.78 | Q4: 10.46 | R4: 16.28 | S4: 16.46 | T4: 15.43 | U4: 15.46 | V4: 11.52 | W4: 11.62 | X4: 10.58 | Y4: 10.75 | AA4: Feb | AB4: 12.38 | AC4: 2.77 | AD4: 2.95 | AE4: 4.08 | AF4: 4.95 | AG4: 5.12
A5: 3 | B5: Mar | C5: 10.35 | D5: 13.7 | E5: 8.37 | F5: 7.35 | G5: 7.78 | H5: 9.42 | I5: 10.18 | J5: 10.01 | K5: 11.91 | L5: 23.41 | M5: 24.06 | N5: 11.73 | O5: 11.11 | P5: 9.82 | Q5: 9.35 | R5: 15.1 | S5: 15.31 | T5: 14.13 | U5: 14.14 | V5: 10.48 | W5: 10.59 | X5: 9.62 | Y5: 9.85 | AA5: Mar | AB5: 10.64 | AC5: 2.57 | AD5: 3.44 | AE5: 3.83 | AF5: 4.62 | AG5: 4.26
A6: 4 | B6: Apr | C6: 5.94 | D6: 8.08 | E6: 4.69 | F6: 4.07 | G6: 4.5 | H6: 5.86 | I6: 6.59 | J6: 5.4 | K6: 7.22 | L6: 14.4 | M6: 14.93 | N6: 6.88 | O6: 6.09 | P6: 5.66 | Q6: 5.12 | R6: 8.88 | S6: 9.12 | T6: 7.95 | U6: 7.91 | V6: 5.93 | W6: 6.04 | X6: 5.45 | Y6: 5.69 | AA6: Apr | AB6: 5.69 | AC6: 1.43 | AD6: 2.4 | AE6: 2.25 | AF6: 2.46 | AG6: 1.89
A7: 5 | B7: May | C7: 2.81 | D7: 4.08 | E7: 2.07 | F7: 1.74 | G7: 2.03 | H7: 2.96 | I7: 3.23 | J7: 2.52 | K7: 3.84 | L7: 7.98 | M7: 8.31 | N7: 3.45 | O7: 2.3 | P7: 2.73 | Q7: 1.86 | R7: 4.44 | S7: 4.62 | T7: 3.27 | U7: 3.2 | V7: 2.68 | W7: 2.77 | X7: 2.24 | Y7: 2.54 | AA7: May | AB7: 2.66 | AC7: 0.39 | AD7: 0.72 | AE7: 0.88 | AF7: 0.81 | AG7: 0.43
A8: 6 | B8: Jun | C8: 0.83 | D8: 1.37 | E8: 0.54 | F8: 0.44 | G8: 0.53 | H8: 0.92 | I8: 0.99 | J8: 0.72 | K8: 1.34 | L8: 3.24 | M8: 3.38 | N8: 1.16 | O8: 0.48 | P8: 0.85 | Q8: 0.38 | R8: 1.43 | S8: 1.5 | T8: 0.72 | U8: 0.7 | V8: 0.72 | W8: 0.75 | X8: 0.5 | Y8: 0.67 | AA8: Jun | AB8: 0.77 | AC8: 0.05 | AD8: 0.1 | AE8: 0.2 | AF8: 0.14 | AG8: 0.04
A9: 7 | B9: Jul | C9: 0.09 | D9: 0.25 | E9: 0.03 | F9: 0.02 | G9: 0.02 | H9: 0.1 | I9: 0.12 | J9: 0.08 | K9: 0.31 | L9: 0.99 | M9: 1.05 | N9: 0.21 | O9: 0 | P9: 0.11 | Q9: 0 | R9: 0.22 | S9: 0.25 | T9: 0 | U9: 0 | V9: 0.05 | W9: 0.05 | X9: 0 | Y9: 0.02 | AA9: Jul | AB9: 0.09 | AC9: 0 | AD9: 0 | AE9: 0 | AF9: 0 | AG9: 0
A10: 8 | B10: Aug | C10: 0.19 | D10: 0.42 | E10: 0.08 | F10: 0.06 | G10: 0.06 | H10: 0.19 | I10: 0.24 | J10: 0.16 | K10: 0.51 | L10: 1.5 | M10: 1.57 | N10: 0.35 | O10: 0 | P10: 0.21 | Q10: 0 | R10: 0.39 | S10: 0.44 | T10: 0 | U10: 0 | V10: 0.12 | W10: 0.13 | X10: 0 | Y10: 0.06 | AA10: Aug | AB10: 0.18 | AC10: 0 | AD10: 0 | AE10: 0 | AF10: 0 | AG10: 0
A11: 9 | B11: Sep | C11: 1.47 | D11: 2.23 | E11: 0.98 | F11: 0.78 | G11: 0.93 | H11: 1.31 | I11: 1.5 | J11: 1.39 | K11: 2.19 | L11: 4.7 | M11: 4.85 | N11: 1.91 | O11: 0.64 | P11: 1.47 | Q11: 0.39 | R11: 2.38 | S11: 2.45 | T11: 0.63 | U11: 0.61 | V11: 1.3 | W11: 1.35 | X11: 0.36 | Y11: 0.85 | AA11: Sep | AB11: 1.48 | AC11: 0 | AD11: 0 | AE11: 0.14 | AF11: 0.13 | AG11: 0.01
A12: 10 | B12: Oct | C12: 4.1 | D12: 5.73 | E12: 3.07 | F12: 2.6 | G12: 2.98 | H12: 3.45 | I12: 3.66 | J12: 4.15 | K12: 5.28 | L12: 10.62 | M12: 10.91 | N12: 4.91 | O12: 3.37 | P12: 3.99 | Q12: 2.68 | R12: 6.23 | S12: 6.38 | T12: 4.04 | U12: 3.92 | V12: 3.95 | W12: 4.04 | X12: 2.48 | Y12: 3 | AA12: Oct | AB12: 4.48 | AC12: 0.23 | AD12: 0.28 | AE12: 0.77 | AF12: 1.32 | AG12: 0.66
